Workbook

Sheet VIAJES
A1: Date or Period | B1: Group Name | C1: Payroll | D1: Driver Name | E1: Trip Count | F1: Idle Time | G1: Net Drive Time | H1: Driven Distance
A2: Periodo o Fecha | B2: Nombre del Grupo | C2: Nomina | D2: Nombre del Operador | E2: Viajes Contados | F2: Tiempo en Ralenti | G2: Tiempo Neto de Conducción | H2: Distancia Conducida
B3: LIPU COLIMA | C3: 14217446 | D3: ABARCA MARQUEZ JORGE ABRAHAM | E3: 32 | F3: 0.22569444 | G3: 0.88263889 | H3: 706.14
B4: LIPU COLIMA | C4: 14221921 | D4: ALONSO ALVA JESUS ALBERTO | E4: 52 | F4: 0.33958333 | G4: 1.21875 | H4: 1176.79
B5: LIPU COLIMA | C5: 14215986 | D5: ANGUIANO JIMENEZ JUAN MANUEL | E5: 27 | F5: 0.40833333 | G5: 0.74305556 | H5: 498.32
B6: LIPU COLIMA | C6: 14218817 | D6: ARCEO GAMA SILVESTRE | E6: 17 | F6: 0.16875 | G6: 0.21944444 | H6: 181
B7: LIPU COLIMA | C7: 14222224 | D7: BARRETO LEYVA FEDERICO | E7: 46 | F7: 0.27013889 | G7: 1.3256944 | H7: 1146.19
B8: LIPU COLIMA | C8: 14110812 | D8: C.CONSTANTE RODRIGUEZ MARVIN J | E8: 15 | F8: 0.020138889 | G8: 0.4 | H8: 484.61
B9: LIPU COLIMA | C9: 14222299 | D9: CABRERA MARTINEZ JUAN JOSE | E9: 87 | F9: 0.34305556 | G9: 1.6395833 | H9: 1270.94
B10: LIPU COLIMA | C10: 14108427 | D10: CASTELLANOS GOMEZ MARTIN | E10: 25 | F10: 0.21527778 | G10: 0.875 | H10: 773.72
B11: LIPU COLIMA | C11: 14111261 | D11: CASTILLO GRADILLA OSCAR EMILIO | E11: 29 | F11: 0.19305556 | G11: 1.025 | H11: 859.1
B12: LIPU COLIMA | C12: 14217288 | D12: CERNAS LOPEZ CLEMENTE MARTIN | E12: 23 | F12: 0.2375 | G12: 0.49027778 | H12: 330.05
B13: LIPU COLIMA | C13: 14216383 | D13: CERVANTES CONTRERAS NICOLAS | E13: 29 | F13: 0.16736111 | G13: 0.70833333 | H13: 501.93
B14: LIPU COLIMA | C14: 14221929 | D14: CONTRERAS RUIZ JOSE GUADALUP | E14: 20 | F14: 0.082638889 | G14: 0.55069444 | H14: 554.67
... B45: LIPU COLIMA | C45: 14222163 | D45: OCHOA GUERRERO EDGAR JESUS | E45: 47 | F45: 0.23194444 | G45: 0.91805556 | H45: 762.29
B46: LIPU COLIMA | D46: P.CHAVEZ PAREDES JUAN MANUEL | E46: 3 | F46: 0.0027777778 | G46: 0.034027778 | H46: 47.52
B47: LIPU COLIMA | D47: P.FARIAS BARAJAS DIEGO FAVIAN | E47: 2 | F47: 0.00625 | G47: 0.048611111 | H47: 54.55
B48: LIPU COLIMA | D48: P.GOIYTIA MANZANO ALONSO FAVI | E48: 8 | F48: 0.040972222 | G48: 0.11736111 | H48: 92.9
B49: LIPU COLIMA | D49: P.GONZALEZ GILDO EFRAIN | E49: 5 | F49: 0.01875 | G49: 0.092361111 | H49: 100.08
B50: LIPU COLIMA | D50: P.GUERRERO BELTRAN CARLOS ALEJ | E50: 4 | F50: 0.017361111 | G50: 0.048611111 | H50: 46.65
B51: LIPU COLIMA | D51: P.LEE GUTIERREZ JOSE GUADALUPE | E51: 4 | F51: 0.013888889 | G51: 0.098611111 | H51: 108.53
B52: LIPU COLIMA | D52: P.NUÑIEZ TORRES RICARDO | E52: 1 | F52: 0.0034722222 | G52: 0.0020833333 | H52: 0.49
B53: LIPU COLIMA | D53: P.REYNOSO PEREZ CARLOS SALVADO | E53: 1 | F53: 0.015277778 | G53: 0.059722222 | H53: 68.7
B54: LIPU COLIMA | D54: P.ROMERO RAMIREZ ARMANDO | E54: 5 | F54: 0.034722222 | G54: 0.12430556 | H54: 112.3
B55: LIPU COLIMA | D55: P.SANDOVAL RAMOS CRISTI EVELYN | E55: 5 | F55: 0.0048611111 | G55: 0.060416667 | H55: 59.44
B56: LIPU COLIMA | C56: 14218381 | D56: PACO MENDEZ FABIAN | E56: 32 | F56: 0.27708333 | G56: 0.75069444 | H56: 446.44
B57: LIPU COLIMA | C57: 14111999 | D57: PEREZ MARTINEZ TIMOTEO | E57: 38 | F57: 0.19097222 | G57: 1.0090278 | H57: 802.11
B58: LIPU COLIMA | C58: 14213259 | D58: PINTO HERNANDEZ ANYELO ALBERTO | E58: 58 | F58: 0.39652778 | G58: 1.4090278 | H58: 1087.04
B59: LIPU COLIMA | C59: 14221966 | D59: PUGA CORTES JOSE MARIA | E59: 34 | F59: 0.22986111 | G59: 0.77638889 | H59: 552.22
B60: LIPU COLIMA | C60: 14217374 | D60: RAMIREZ AVILES GILDARDO | E60: 34 | F60: 0.29375 | G60: 0.95416667 | H60: 478.61
B61: LIPU COLIMA | C61: 14108047 | D61: RAMIREZ VALDEZ SALVADOR | E61: 16 | F61: 0.093055556 | G61: 0.24444444 | H61: 186.87
B62: LIPU COLIMA | C62: 14106267 | D62: RAMOS HERNANDEZ JOSE GABRIEL | E62: 39 | F62: 0.14513889 | G62: 0.95486111 | H62: 532.04
B63: LIPU COLIMA | C63: 14111321 | D63: RAMOS RAMIREZ ROBERTO | E63: 25 | F63: 0.19027778 | G63: 0.34652778 | H63: 198.97
B64: LIPU COLIMA | C64: 14102637 | D64: RIVERA RENTERIA ELIAS | E64: 37 | F64: 0.31805556 | G64: 0.85902778 | H64: 407.67
B65: LIPU COLIMA | C65: 14102638 | D65: RIVERA RENTERIA OCTAVIO | E65: 36 | F65: 0.15277778 | G65: 0.77291667 | H65: 485.34
B66: LIPU COLIMA | C66: 14218735 | D66: RIZO LOPEZ FERNANDO ULISES | E66: 33 | F66: 0.090972222 | G66: 0.90208333 | H66: 691.5
B67: LIPU COLIMA | C67: 14220077 | D67: RODARTE QUINTANA MARCO ANTONIO | E67: 40 | F67: 0.26458333 | G67: 0.93263889 | H67: 663.23
... B89: LIPU COLIMA | C89: 14106257 | D89: ZAMORA VENCES JOSE LUIS | E89: 29 | F89: 0.44166667 | G89: 1.64375 | H89: 1666.86

Sheet EVENTOS
B1: Nombre del Operador | C1: Nombre del Evento | D1: Total Ocurridos | I1: TRADUCCIONES
B2: DRIVER NAME | C2: EVENT NAME | D2: TOTAL OCURRED | E2: TRADUCCIÓN | F2: LLAVE | I2: EVENTO | J2: TRADUCCIÓN
B3: ABARCA MARQUEZ JORGE ABRAHAM | C3: Freno nivel medio | D3: 1 | E3: =VLOOKUP(C3,I:J,2,0) -> FrMed | F3: =E3&" "&B3 -> FrMed ABARCA MARQUEZ JORGE ABRAHAM | I3: Aceleración nivel alto | J3: AcAlto
B4: ABARCA MARQUEZ JORGE ABRAHAM | C4: Giro a la der. nivel bajo | D4: 3 | E4: =VLOOKUP(C4,I:J,2,0) -> GirBajo | F4: =E4&" "&B4 -> GirBajo ABARCA MARQUEZ JORGE ABRAHAM | I4: Aceleración nivel medio | J4: AcMed
B5: ABARCA MARQUEZ JORGE ABRAHAM | C5: Giro a la izq. nivel bajo | D5: 5 | E5: =VLOOKUP(C5,I:J,2,0) -> GirBajo | F5: =E5&" "&B5 -> GirBajo ABARCA MARQUEZ JORGE ABRAHAM | I5: ADAS - Camera blocked
B6: ABARCA MARQUEZ JORGE ABRAHAM | C6: Giro a la izq. nivel medio | D6: 2 | E6: =VLOOKUP(C6,I:J,2,0) -> GirMed | F6: =E6&" "&B6 -> GirMed ABARCA MARQUEZ JORGE ABRAHAM | I6: ADAS - Forward Collision Warning (FCW)
B7: ALONSO ALVA JESUS ALBERTO | C7: Aceleración nivel alto | D7: 2 | E7: =VLOOKUP(C7,I:J,2,0) -> AcAlto | F7: =E7&" "&B7 -> AcAlto ALONSO ALVA JESUS ALBERTO | I7: ADAS - Forward Proximity Warning (FPW)
B8: ALONSO ALVA JESUS ALBERTO | C8: Giro a la der. nivel bajo | D8: 10 | E8: =VLOOKUP(C8,I:J,2,0) -> GirBajo | F8: =E8&" "&B8 -> GirBajo ALONSO ALVA JESUS ALBERTO | I8: ADAS - LDW Left
B9: ALONSO ALVA JESUS ALBERTO | C9: Giro a la der. nivel medio | D9: 2 | E9: =VLOOKUP(C9,I:J,2,0) -> GirMed | F9: =E9&" "&B9 -> GirMed ALONSO ALVA JESUS ALBERTO | I9: ADAS - LDW Rigth
B10: ALONSO ALVA JESUS ALBERTO | C10: Velocidad nivel bajo en carretera | D10: 67 | E10: =VLOOKUP(C10,I:J,2,0) -> VelBajo | F10: =E10&" "&B10 -> VelBajo ALONSO ALVA JESUS ALBERTO | I10: ADAS - Low visibility
B11: ANGUIANO JIMENEZ JUAN MANUEL | C11: Aceleración nivel alto | D11: 6 | E11: =VLOOKUP(C11,I:J,2,0) -> AcAlto | F11: =E11&" "&B11 -> AcAlto ANGUIANO JIMENEZ JUAN MANUEL | I11: ADAS - non recording
B12: ANGUIANO JIMENEZ JUAN MANUEL | C12: Freno nivel alto | D12: 1 | E12: =VLOOKUP(C12,I:J,2,0) -> FrAlto | F12: =E12&" "&B12 -> FrAlto ANGUIANO JIMENEZ JUAN MANUEL | I12: ADAS - PCW
B13: ANGUIANO JIMENEZ JUAN MANUEL | C13: Giro a la der. nivel bajo | D13: 11 | E13: =VLOOKUP(C13,I:J,2,0) -> GirBajo | F13: =E13&" "&B13 -> GirBajo ANGUIANO JIMENEZ JUAN MANUEL | I13: ADAS - SDA
B14: ANGUIANO JIMENEZ JUAN MANUEL | C14: Giro a la der. nivel medio | D14: 6 | E14: =VLOOKUP(C14,I:J,2,0) -> GirMed | F14: =E14&" "&B14 -> GirMed ANGUIANO JIMENEZ JUAN MANUEL | I14: Freno nivel alto | J14: FrAlto
B15: ANGUIANO JIMENEZ JUAN MANUEL | C15: Giro a la izq. nivel bajo | D15: 1 | E15: =VLOOKUP(C15,I:J,2,0) -> GirBajo | F15: =E15&" "&B15 -> GirBajo ANGUIANO JIMENEZ JUAN MANUEL | I15: Freno nivel bajo | J15: FrBajo
B16: ANGUIANO JIMENEZ JUAN MANUEL | C16: Velocidad nivel bajo en carretera | D16: 5 | E16: =VLOOKUP(C16,I:J,2,0) -> VelBajo | F16: =E16&" "&B16 -> VelBajo ANGUIANO JIMENEZ JUAN MANUEL | I16: Freno nivel medio | J16: FrMed
B17: ARCEO GAMA SILVESTRE | C17: Aceleración nivel alto | D17: 3 | E17: =VLOOKUP(C17,I:J,2,0) -> AcAlto | F17: =E17&" "&B17 -> AcAlto ARCEO GAMA SILVESTRE | I17: Velocidad nivel alto en carretera | J17: VelAlto
B18: ARCEO GAMA SILVESTRE | C18: Giro a la der. nivel medio | D18: 1 | E18: =VLOOKUP(C18,I:J,2,0) -> GirMed | F18: =E18&" "&B18 -> GirMed ARCEO GAMA SILVESTRE | I18: Velocidad nivel bajo en carretera | J18: VelBajo
B19: ARCEO GAMA SILVESTRE | C19: Velocidad nivel bajo en carretera | D19: 3 | E19: =VLOOKUP(C19,I:J,2,0) -> VelBajo | F19: =E19&" "&B19 -> VelBajo ARCEO GAMA SILVESTRE | I19: Velocidad nivel medio en carretera | J19: VelMed
B20: BARRETO LEYVA FEDERICO | C20: Aceleración nivel alto | D20: 11 | E20: =VLOOKUP(C20,I:J,2,0) -> AcAlto | F20: =E20&" "&B20 -> AcAlto BARRETO LEYVA FEDERICO | I20: Giro a la izq. nivel alto | J20: GirAlto
B21: BARRETO LEYVA FEDERICO | C21: Aceleración nivel medio | D21: 17 | E21: =VLOOKUP(C21,I:J,2,0) -> AcMed | F21: =E21&" "&B21 -> AcMed BARRETO LEYVA FEDERICO | I21: Giro a la izq. nivel bajo | J21: GirBajo
B22: BARRETO LEYVA FEDERICO | C22: Freno nivel bajo | D22: 2 | E22: =VLOOKUP(C22,I:J,2,0) -> FrBajo | F22: =E22&" "&B22 -> FrBajo BARRETO LEYVA FEDERICO | I22: Giro a la izq. nivel medio | J22: GirMed
B23: BARRETO LEYVA FEDERICO | C23: Freno nivel medio | D23: 1 | E23: =VLOOKUP(C23,I:J,2,0) -> FrMed | F23: =E23&" "&B23 -> FrMed BARRETO LEYVA FEDERICO | I23: Giro a la der. nivel alto | J23: GirAlto
B24: BARRETO LEYVA FEDERICO | C24: Giro a la der. nivel alto | D24: 1 | E24: =VLOOKUP(C24,I:J,2,0) -> GirAlto | F24: =E24&" "&B24 -> GirAlto BARRETO LEYVA FEDERICO | I24: Giro a la der. nivel bajo | J24: GirBajo
B25: BARRETO LEYVA FEDERICO | C25: Giro a la der. nivel bajo | D25: 34 | E25: =VLOOKUP(C25,I:J,2,0) -> GirBajo | F25: =E25&" "&B25 -> GirBajo BARRETO LEYVA FEDERICO | I25: Giro a la der. nivel medio | J25: GirMed
B26: BARRETO LEYVA FEDERICO | C26: Giro a la der. nivel medio | D26: 17 | E26: =VLOOKUP(C26,I:J,2,0) -> GirMed | F26: =E26&" "&B26 -> GirMed BARRETO LEYVA FEDERICO
B27: BARRETO LEYVA FEDERICO | C27: Giro a la izq. nivel alto | D27: 2 | E27: =VLOOKUP(C27,I:J,2,0) -> GirAlto | F27: =E27&" "&B27 -> GirAlto BARRETO LEYVA FEDERICO
B28: BARRETO LEYVA FEDERICO | C28: Giro a la izq. nivel bajo | D28: 28 | E28: =VLOOKUP(C28,I:J,2,0) -> GirBajo | F28: =E28&" "&B28 -> GirBajo BARRETO LEYVA FEDERICO
B29: BARRETO LEYVA FEDERICO | C29: Giro a la izq. nivel medio | D29: 8 | E29: =VLOOKUP(C29,I:J,2,0) -> GirMed | F29: =E29&" "&B29 -> GirMed BARRETO LEYVA FEDERICO
B30: BARRETO LEYVA FEDERICO | C30: Velocidad nivel bajo en carretera | D30: 1 | E30: =VLOOKUP(C30,I:J,2,0) -> VelBajo | F30: =E30&" "&B30 -> VelBajo BARRETO LEYVA FEDERICO
B31: C.CONSTANTE RODRIGUEZ MARVIN J | C31: Freno nivel bajo | D31: 4 | E31: =VLOOKUP(C31,I:J,2,0) -> FrBajo | F31: =E31&" "&B31 -> FrBajo C.CONSTANTE RODRIGUEZ MARVIN J
B32: C.CONSTANTE RODRIGUEZ MARVIN J | C32: Freno nivel medio | D32: 1 | E32: =VLOOKUP(C32,I:J,2,0) -> FrMed | F32: =E32&" "&B32 -> FrMed C.CONSTANTE RODRIGUEZ MARVIN J
B33: C.CONSTANTE RODRIGUEZ MARVIN J | C33: Giro a la der. nivel bajo | D33: 26 | E33: =VLOOKUP(C33,I:J,2,0) -> GirBajo | F33: =E33&" "&B33 -> GirBajo C.CONSTANTE RODRIGUEZ MARVIN J
B34: C.CONSTANTE RODRIGUEZ MARVIN J | C34: Giro a la der. nivel medio | D34: 5 | E34: =VLOOKUP(C34,I:J,2,0) -> GirMed | F34: =E34&" "&B34 -> GirMed C.CONSTANTE RODRIGUEZ MARVIN J
B35: C.CONSTANTE RODRIGUEZ MARVIN J | C35: Giro a la izq. nivel alto | D35: 1 | E35: =VLOOKUP(C35,I:J,2,0) -> GirAlto | F35: =E35&" "&B35 -> GirAlto C.CONSTANTE RODRIGUEZ MARVIN J
B36: C.CONSTANTE RODRIGUEZ MARVIN J | C36: Giro a la izq. nivel bajo | D36: 17 | E36: =VLOOKUP(C36,I:J,2,0) -> GirBajo | F36: =E36&" "&B36 -> GirBajo C.CONSTANTE RODRIGUEZ MARVIN J
B37: C.CONSTANTE RODRIGUEZ MARVIN J | C37: Giro a la izq. nivel medio | D37: 4 | E37: =VLOOKUP(C37,I:J,2,0) -> GirMed | F37: =E37&" "&B37 -> GirMed C.CONSTANTE RODRIGUEZ MARVIN J
... B335: ZAMORA VENCES JOSE LUIS | C335: Velocidad nivel bajo en carretera | D335: 159 | E335: =VLOOKUP(C335,I:J,2,0) -> VelBajo | F335: =E335&" "&B335 -> VelBajo ZAMORA VENCES JOSE LUIS
E336: =VLOOKUP(C336,I:J,2,0) -> #N/A | F336: =E336&" "&B336 -> #N/A
E337: =VLOOKUP(C337,I:J,2,0) -> #N/A | F337: =E337&" "&B337 -> #N/A
...

Sheet SCORE
A1: Date or Period Periodo o Fecha | B1: Group Name Nombre del Grupo | C1: Payroll Nomina | D1: Driver Name Nombre del Operador | E1: Trip Count Viajes Contados | F1: Idle Time Tiempo en Ralenti | G1: Net Drive Time Tiempo Neto de Conducción | H1: Driven Distance Distancia Conducida | S1: EVENTOS/EVENT | AE1: Points Puntos | AF1: Points per 100 h Puntos x 100 h | AG1: Score Puntaje
S2: AcAlto | T2: AcMed | U2: AcBajo | V2: FrAlto | W2: FrMed | X2: FrBajo | Y2: GirAlto | Z2: GirMed | AA2: GirBajo | AB2: VelAlto | AC2: VelMed | AD2: VelBajo
B3: LIPU COLIMA | C3: 14217446 | D3: ABARCA MARQUEZ JORGE ABRAHAM | E3: =VLOOKUP(D3,VIAJES!$D:$E,2,FALSE) -> 32 | F3: =VLOOKUP(D3,VIAJES!$D:$F,3,FALSE) -> 0.22569444 | G3: =VLOOKUP(D3,VIAJES!$D:$G,4,FALSE) -> 0.88263889 | H3: =VLOOKUP(D3,VIAJES!$D:$H,5,FALSE) -> 706.14 | S3: =IFERROR(INDEX(EVENTOS!$D:$D,MATCH(SCORE!S$2&" "&SCORE!$D3,EVENTOS!$F:$F,0)),0) -> 0 | T3: =IFERROR(INDEX(EVENTOS!$D:$D,MATCH(SCORE!T$2&" "&SCORE!$D3,EVENTOS!$F:$F,0)),0) -> 0 | U3: =IFERROR(INDEX(EVENTOS!$D:$D,MATCH(SCORE!U$2&" "&SCORE!$D3,EVENTOS!$F:$F,0)),0) -> 0 | V3: =IFERROR(INDEX(EVENTOS!$D:$D,MATCH(SCORE!V$2&" "&SCORE!$D3,EVENTOS!$F:$F,0)),0) -> 0 | W3: =IFERROR(INDEX(EVENTOS!$D:$D,MATCH(SCORE!W$2&" "&SCORE!$D3,EVENTOS!$F:$F,0)),0) -> 1 | X3: =IFERROR(INDEX(EVENTOS!$D:$D,MATCH(SCORE!X$2&" "&SCORE!$D3,EVENTOS!$F:$F,0)),0) -> 0 | Y3: =SUMIFS(EVENTOS!$D:$D, EVENTOS!$B:$B, D3, EVENTOS!$E:$E, "*GirAlto*") -> 0 | Z3: =SUMIFS(EVENTOS!$D:$D, EVENTOS!$B:$B, D3, EVENTOS!$E:$E, "*GirMed*") -> 2 | AA3: =SUMIFS(EVENTOS!$D:$D, EVENTOS!$B:$B, D3, EVENTOS!$E:$E, "*GirBajo*") -> 8 | AB3: =IFERROR(INDEX(EVENTOS!$D:$D,MATCH(SCORE!AB$2&" "&SCORE!$D3,EVENTOS!$F:$F,0)),0) -> 0 | AC3: =IFERROR(INDEX(EVENTOS!$D:$D,MATCH(SCORE!AC$2&" "&SCORE!$D3,EVENTOS!$F:$F,0)),0) -> 0 | AD3: =IFERROR(INDEX(EVENTOS!$D:$D,MATCH(SCORE!AD$2&" "&SCORE!$D3,EVENTOS!$F:$F,0)),0) -> 0 | AE3: =((S3+V3+Y3+AB3)*50)+((T3+W3+Z3+AC3)*25)+((U3+X3+AA3+AD3)*5) -> 115 | AF3: =AE3/(G3*24)*100 -> 542.87962 | AG3: =IF(D3<>"",IF(AF3>=30000,5,ROUNDDOWN((((5-95)*(AF3-0))/(30000-0))+95,0)),"") -> 93
B4: LIPU COLIMA | C4: 14221921 | D4: ALONSO ALVA JESUS ALBERTO | E4: =VLOOKUP(D4,VIAJES!$D:$E,2,FALSE) -> 52 | F4: =VLOOKUP(D4,VIAJES!$D:$F,3,FALSE) -> 0.33958333 | G4: =VLOOKUP(D4,VIAJES!$D:$G,4,FALSE) -> 1.21875 | H4: =VLOOKUP(D4,VIAJES!$D:$H,5,FALSE) -> 1176.79 | S4: =IFERROR(INDEX(EVENTOS!$D:$D,MATCH(SCORE!S$2&" "&SCORE!$D4,EVENTOS!$F:$F,0)),0) -> 2 | T4: =IFERROR(INDEX(EVENTOS!$D:$D,MATCH(SCORE!T$2&" "&SCORE!$D4,EVENTOS!$F:$F,0)),0) -> 0 | U4: =IFERROR(INDEX(EVENTOS!$D:$D,MATCH(SCORE!U$2&" "&SCORE!$D4,EVENTOS!$F:$F,0)),0) -> 0 | V4: =IFERROR(INDEX(EVENTOS!$D:$D,MATCH(SCORE!V$2&" "&SCORE!$D4,EVENTOS!$F:$F,0)),0) -> 0 | W4: =IFERROR(INDEX(EVENTOS!$D:$D,MATCH(SCORE!W$2&" "&SCORE!$D4,EVENTOS!$F:$F,0)),0) -> 0 | X4: =IFERROR(INDEX(EVENTOS!$D:$D,MATCH(SCORE!X$2&" "&SCORE!$D4,EVENTOS!$F:$F,0)),0) -> 0 | Y4: =SUMIFS(EVENTOS!$D:$D, EVENTOS!$B:$B, D4, EVENTOS!$E:$E, "*GirAlto*") -> 0 | Z4: =SUMIFS(EVENTOS!$D:$D, EVENTOS!$B:$B, D4, EVENTOS!$E:$E, "*GirMed*") -> 2 | AA4: =SUMIFS(EVENTOS!$D:$D, EVENTOS!$B:$B, D4, EVENTOS!$E:$E, "*GirBajo*") -> 10 | AB4: =IFERROR(INDEX(EVENTOS!$D:$D,MATCH(SCORE!AB$2&" "&SCORE!$D4,EVENTOS!$F:$F,0)),0) -> 0 | AC4: =IFERROR(INDEX(EVENTOS!$D:$D,MATCH(SCORE!AC$2&" "&SCORE!$D4,EVENTOS!$F:$F,0)),0) -> 0 | AD4: =IFERROR(INDEX(EVENTOS!$D:$D,MATCH(SCORE!AD$2&" "&SCORE!$D4,EVENTOS!$F:$F,0)),0) -> 67 | AE4: =((S4+V4+Y4+AB4)*50)+((T4+W4+Z4+AC4)*25)+((U4+X4+AA4+AD4)*5) -> 535 | AF4: =AE4/(G4*24)*100 -> 1829.0598 | AG4: =IF(D4<>"",IF(AF4>=30000,5,ROUNDDOWN((((5-95)*(AF4-0))/(30000-0))+95,0)),"") -> 89 | AI4: 95 A 90
B5: LIPU COLIMA | C5: 14215986 | D5: ANGUIANO JIMENEZ JUAN MANUEL | E5: =VLOOKUP(D5,VIAJES!$D:$E,2,FALSE) -> 27 | F5: =VLOOKUP(D5,VIAJES!$D:$F,3,FALSE) -> 0.40833333 | G5: =VLOOKUP(D5,VIAJES!$D:$G,4,FALSE) -> 0.74305556 | H5: =VLOOKUP(D5,VIAJES!$D:$H,5,FALSE) -> 498.32 | S5: =IFERROR(INDEX(EVENTOS!$D:$D,MATCH(SCORE!S$2&" "&SCORE!$D5,EVENTOS!$F:$F,0)),0) -> 6 | T5: =IFERROR(INDEX(EVENTOS!$D:$D,MATCH(SCORE!T$2&" "&SCORE!$D5,EVENTOS!$F:$F,0)),0) -> 0 | U5: =IFERROR(INDEX(EVENTOS!$D:$D,MATCH(SCORE!U$2&" "&SCORE!$D5,EVENTOS!$F:$F,0)),0) -> 0 | V5: =IFERROR(INDEX(EVENTOS!$D:$D,MATCH(SCORE!V$2&" "&SCORE!$D5,EVENTOS!$F:$F,0)),0) -> 1 | W5: =IFERROR(INDEX(EVENTOS!$D:$D,MATCH(SCORE!W$2&" "&SCORE!$D5,EVENTOS!$F:$F,0)),0) -> 0 | X5: =IFERROR(INDEX(EVENTOS!$D:$D,MATCH(SCORE!X$2&" "&SCORE!$D5,EVENTOS!$F:$F,0)),0) -> 0 | Y5: =SUMIFS(EVENTOS!$D:$D, EVENTOS!$B:$B, D5, EVENTOS!$E:$E, "*GirAlto*") -> 0 | Z5: =SUMIFS(EVENTOS!$D:$D, EVENTOS!$B:$B, D5, EVENTOS!$E:$E, "*GirMed*") -> 6 | AA5: =SUMIFS(EVENTOS!$D:$D, EVENTOS!$B:$B, D5, EVENTOS!$E:$E, "*GirBajo*") -> 12 | AB5: =IFERROR(INDEX(EVENTOS!$D:$D,MATCH(SCORE!AB$2&" "&SCORE!$D5,EVENTOS!$F:$F,0)),0) -> 0 | AC5: =IFERROR(INDEX(EVENTOS!$D:$D,MATCH(SCORE!AC$2&" "&SCORE!$D5,EVENTOS!$F:$F,0)),0) -> 0 | AD5: =IFERROR(INDEX(EVENTOS!$D:$D,MATCH(SCORE!AD$2&" "&SCORE!$D5,EVENTOS!$F:$F,0)),0) -> 5 | AE5: =((S5+V5+Y5+AB5)*50)+((T5+W5+Z5+AC5)*25)+((U5+X5+AA5+AD5)*5) -> 585 | AF5: =AE5/(G5*24)*100 -> 3280.3738 | AG5: =IF(D5<>"",IF(AF5>=30000,5,ROUNDDOWN((((5-95)*(AF5-0))/(30000-0))+95,0)),"") -> 85 | AI5: 89 A 76
B6: LIPU COLIMA | C6: 14218817 | D6: ARCEO GAMA SILVESTRE | E6: =VLOOKUP(D6,VIAJES!$D:$E,2,FALSE) -> 17 | F6: =VLOOKUP(D6,VIAJES!$D:$F,3,FALSE) -> 0.16875 | G6: =VLOOKUP(D6,VIAJES!$D:$G,4,FALSE) -> 0.21944444 | H6: =VLOOKUP(D6,VIAJES!$D:$H,5,FALSE) -> 181 | S6: =IFERROR(INDEX(EVENTOS!$D:$D,MATCH(SCORE!S$2&" "&SCORE!$D6,EVENTOS!$F:$F,0)),0) -> 3 | T6: =IFERROR(INDEX(EVENTOS!$D:$D,MATCH(SCORE!T$2&" "&SCORE!$D6,EVENTOS!$F:$F,0)),0) -> 0 | U6: =IFERROR(INDEX(EVENTOS!$D:$D,MATCH(SCORE!U$2&" "&SCORE!$D6,EVENTOS!$F:$F,0)),0) -> 0 | V6: =IFERROR(INDEX(EVENTOS!$D:$D,MATCH(SCORE!V$2&" "&SCORE!$D6,EVENTOS!$F:$F,0)),0) -> 0 | W6: =IFERROR(INDEX(EVENTOS!$D:$D,MATCH(SCORE!W$2&" "&SCORE!$D6,EVENTOS!$F:$F,0)),0) -> 0 | X6: =IFERROR(INDEX(EVENTOS!$D:$D,MATCH(SCORE!X$2&" "&SCORE!$D6,EVENTOS!$F:$F,0)),0) -> 0 | Y6: =SUMIFS(EVENTOS!$D:$D, EVENTOS!$B:$B, D6, EVENTOS!$E:$E, "*GirAlto*") -> 0 | Z6: =SUMIFS(EVENTOS!$D:$D, EVENTOS!$B:$B, D6, EVENTOS!$E:$E, "*GirMed*") -> 1 | AA6: =SUMIFS(EVENTOS!$D:$D, EVENTOS!$B:$B, D6, EVENTOS!$E:$E, "*GirBajo*") -> 0 | AB6: =IFERROR(INDEX(EVENTOS!$D:$D,MATCH(SCORE!AB$2&" "&SCORE!$D6,EVENTOS!$F:$F,0)),0) -> 0 | AC6: =IFERROR(INDEX(EVENTOS!$D:$D,MATCH(SCORE!AC$2&" "&SCORE!$D6,EVENTOS!$F:$F,0)),0) -> 0 | AD6: =IFERROR(INDEX(EVENTOS!$D:$D,MATCH(SCORE!AD$2&" "&SCORE!$D6,EVENTOS!$F:$F,0)),0) -> 3 | AE6: =((S6+V6+Y6+AB6)*50)+((T6+W6+Z6+AC6)*25)+((U6+X6+AA6+AD6)*5) -> 190 | AF6: =AE6/(G6*24)*100 -> 3607.5949 | AG6: =IF(D6<>"",IF(AF6>=30000,5,ROUNDDOWN((((5-95)*(AF6-0))/(30000-0))+95,0)),"") -> 84 | AI6: 75 A 61
B7: LIPU COLIMA | C7: 14222224 | D7: BARRETO LEYVA FEDERICO | E7: =VLOOKUP(D7,VIAJES!$D:$E,2,FALSE) -> 46 | F7: =VLOOKUP(D7,VIAJES!$D:$F,3,FALSE) -> 0.27013889 | G7: =VLOOKUP(D7,VIAJES!$D:$G,4,FALSE) -> 1.3256944 | H7: =VLOOKUP(D7,VIAJES!$D:$H,5,FALSE) -> 1146.19 | S7: =IFERROR(INDEX(EVENTOS!$D:$D,MATCH(SCORE!S$2&" "&SCORE!$D7,EVENTOS!$F:$F,0)),0) -> 11 | T7: =IFERROR(INDEX(EVENTOS!$D:$D,MATCH(SCORE!T$2&" "&SCORE!$D7,EVENTOS!$F:$F,0)),0) -> 17 | U7: =IFERROR(INDEX(EVENTOS!$D:$D,MATCH(SCORE!U$2&" "&SCORE!$D7,EVENTOS!$F:$F,0)),0) -> 0 | V7: =IFERROR(INDEX(EVENTOS!$D:$D,MATCH(SCORE!V$2&" "&SCORE!$D7,EVENTOS!$F:$F,0)),0) -> 0 | W7: =IFERROR(INDEX(EVENTOS!$D:$D,MATCH(SCORE!W$2&" "&SCORE!$D7,EVENTOS!$F:$F,0)),0) -> 1 | X7: =IFERROR(INDEX(EVENTOS!$D:$D,MATCH(SCORE!X$2&" "&SCORE!$D7,EVENTOS!$F:$F,0)),0) -> 2 | Y7: =SUMIFS(EVENTOS!$D:$D, EVENTOS!$B:$B, D7, EVENTOS!$E:$E, "*GirAlto*") -> 3 | Z7: =SUMIFS(EVENTOS!$D:$D, EVENTOS!$B:$B, D7, EVENTOS!$E:$E, "*GirMed*") -> 25 | AA7: =SUMIFS(EVENTOS!$D:$D, EVENTOS!$B:$B, D7, EVENTOS!$E:$E, "*GirBajo*") -> 62 | AB7: =IFERROR(INDEX(EVENTOS!$D:$D,MATCH(SCORE!AB$2&" "&SCORE!$D7,EVENTOS!$F:$F,0)),0) -> 0 | AC7: =IFERROR(INDEX(EVENTOS!$D:$D,MATCH(SCORE!AC$2&" "&SCORE!$D7,EVENTOS!$F:$F,0)),0) -> 0 | AD7: =IFERROR(INDEX(EVENTOS!$D:$D,MATCH(SCORE!AD$2&" "&SCORE!$D7,EVENTOS!$F:$F,0)),0) -> 1 | AE7: =((S7+V7+Y7+AB7)*50)+((T7+W7+Z7+AC7)*25)+((U7+X7+AA7+AD7)*5) -> 2100 | AF7: =AE7/(G7*24)*100 -> 6600.3143 | AG7: =IF(D7<>"",IF(AF7>=30000,5,ROUNDDOWN((((5-95)*(AF7-0))/(30000-0))+95,0)),"") -> 75 | AI7: 60 A 5
B8: LIPU COLIMA | C8: 14110812 | D8: C.CONSTANTE RODRIGUEZ MARVIN J | E8: =VLOOKUP(D8,VIAJES!$D:$E,2,FALSE) -> 15 | F8: =VLOOKUP(D8,VIAJES!$D:$F,3,FALSE) -> 0.020138889 | G8: =VLOOKUP(D8,VIAJES!$D:$G,4,FALSE) -> 0.4 | H8: =VLOOKUP(D8,VIAJES!$D:$H,5,FALSE) -> 484.61 | S8: =IFERROR(INDEX(EVENTOS!$D:$D,MATCH(SCORE!S$2&" "&SCORE!$D8,EVENTOS!$F:$F,0)),0) -> 0 | T8: =IFERROR(INDEX(EVENTOS!$D:$D,MATCH(SCORE!T$2&" "&SCORE!$D8,EVENTOS!$F:$F,0)),0) -> 0 | U8: =IFERROR(INDEX(EVENTOS!$D:$D,MATCH(SCORE!U$2&" "&SCORE!$D8,EVENTOS!$F:$F,0)),0) -> 0 | V8: =IFERROR(INDEX(EVENTOS!$D:$D,MATCH(SCORE!V$2&" "&SCORE!$D8,EVENTOS!$F:$F,0)),0) -> 0 | W8: =IFERROR(INDEX(EVENTOS!$D:$D,MATCH(SCORE!W$2&" "&SCORE!$D8,EVENTOS!$F:$F,0)),0) -> 1 | X8: =IFERROR(INDEX(EVENTOS!$D:$D,MATCH(SCORE!X$2&" "&SCORE!$D8,EVENTOS!$F:$F,0)),0) -> 4 | Y8: =SUMIFS(EVENTOS!$D:$D, EVENTOS!$B:$B, D8, EVENTOS!$E:$E, "*GirAlto*") -> 1 | Z8: =SUMIFS(EVENTOS!$D:$D, EVENTOS!$B:$B, D8, EVENTOS!$E:$E, "*GirMed*") -> 9 | AA8: =SUMIFS(EVENTOS!$D:$D, EVENTOS!$B:$B, D8, EVENTOS!$E:$E, "*GirBajo*") -> 43 | AB8: =IFERROR(INDEX(EVENTOS!$D:$D,MATCH(SCORE!AB$2&" "&SCORE!$D8,EVENTOS!$F:$F,0)),0) -> 4 | AC8: =IFERROR(INDEX(EVENTOS!$D:$D,MATCH(SCORE!AC$2&" "&SCORE!$D8,EVENTOS!$F:$F,0)),0) -> 31 | AD8: =IFERROR(INDEX(EVENTOS!$D:$D,MATCH(SCORE!AD$2&" "&SCORE!$D8,EVENTOS!$F:$F,0)),0) -> 19 | AE8: =((S8+V8+Y8+AB8)*50)+((T8+W8+Z8+AC8)*25)+((U8+X8+AA8+AD8)*5) -> 1605 | AF8: =AE8/(G8*24)*100 -> 16718.75 | AG8: =IF(D8<>"",IF(AF8>=30000,5,ROUNDDOWN((((5-95)*(AF8-0))/(30000-0))+95,0)),"") -> 44
B9: LIPU COLIMA | C9: 14222299 | D9: CABRERA MARTINEZ JUAN JOSE | E9: =VLOOKUP(D9,VIAJES!$D:$E,2,FALSE) -> 87 | F9: =VLOOKUP(D9,VIAJES!$D:$F,3,FALSE) -> 0.34305556 | G9: =VLOOKUP(D9,VIAJES!$D:$G,4,FALSE) -> 1.6395833 | H9: =VLOOKUP(D9,VIAJES!$D:$H,5,FALSE) -> 1270.94 | S9: =IFERROR(INDEX(EVENTOS!$D:$D,MATCH(SCORE!S$2&" "&SCORE!$D9,EVENTOS!$F:$F,0)),0) -> 26 | T9: =IFERROR(INDEX(EVENTOS!$D:$D,MATCH(SCORE!T$2&" "&SCORE!$D9,EVENTOS!$F:$F,0)),0) -> 198 | U9: =IFERROR(INDEX(EVENTOS!$D:$D,MATCH(SCORE!U$2&" "&SCORE!$D9,EVENTOS!$F:$F,0)),0) -> 0 | V9: =IFERROR(INDEX(EVENTOS!$D:$D,MATCH(SCORE!V$2&" "&SCORE!$D9,EVENTOS!$F:$F,0)),0) -> 1 | W9: =IFERROR(INDEX(EVENTOS!$D:$D,MATCH(SCORE!W$2&" "&SCORE!$D9,EVENTOS!$F:$F,0)),0) -> 35 | X9: =IFERROR(INDEX(EVENTOS!$D:$D,MATCH(SCORE!X$2&" "&SCORE!$D9,EVENTOS!$F:$F,0)),0) -> 28 | Y9: =SUMIFS(EVENTOS!$D:$D, EVENTOS!$B:$B, D9, EVENTOS!$E:$E, "*GirAlto*") -> 5 | Z9: =SUMIFS(EVENTOS!$D:$D, EVENTOS!$B:$B, D9, EVENTOS!$E:$E, "*GirMed*") -> 76 | AA9: =SUMIFS(EVENTOS!$D:$D, EVENTOS!$B:$B, D9, EVENTOS!$E:$E, "*GirBajo*") -> 205 | AB9: =IFERROR(INDEX(EVENTOS!$D:$D,MATCH(SCORE!AB$2&" "&SCORE!$D9,EVENTOS!$F:$F,0)),0) -> 0 | AC9: =IFERROR(INDEX(EVENTOS!$D:$D,MATCH(SCORE!AC$2&" "&SCORE!$D9,EVENTOS!$F:$F,0)),0) -> 0 | AD9: =IFERROR(INDEX(EVENTOS!$D:$D,MATCH(SCORE!AD$2&" "&SCORE!$D9,EVENTOS!$F:$F,0)),0) -> 12 | AE9: =((S9+V9+Y9+AB9)*50)+((T9+W9+Z9+AC9)*25)+((U9+X9+AA9+AD9)*5) -> 10550 | AF9: =AE9/(G9*24)*100 -> 26810.673 | AG9: =IF(D9<>"",IF(AF9>=30000,5,ROUNDDOWN((((5-95)*(AF9-0))/(30000-0))+95,0)),"") -> 14
B10: LIPU COLIMA | C10: 14108427 | D10: CASTELLANOS GOMEZ MARTIN | E10: =VLOOKUP(D10,VIAJES!$D:$E,2,FALSE) -> 25 | F10: =VLOOKUP(D10,VIAJES!$D:$F,3,FALSE) -> 0.21527778 | G10: =VLOOKUP(D10,VIAJES!$D:$G,4,FALSE) -> 0.875 | H10: =VLOOKUP(D10,VIAJES!$D:$H,5,FALSE) -> 773.72 | S10: =IFERROR(INDEX(EVENTOS!$D:$D,MATCH(SCORE!S$2&" "&SCORE!$D10,EVENTOS!$F:$F,0)),0) -> 0 | T10: =IFERROR(INDEX(EVENTOS!$D:$D,MATCH(SCORE!T$2&" "&SCORE!$D10,EVENTOS!$F:$F,0)),0) -> 0 | U10: =IFERROR(INDEX(EVENTOS!$D:$D,MATCH(SCORE!U$2&" "&SCORE!$D10,EVENTOS!$F:$F,0)),0) -> 0 | V10: =IFERROR(INDEX(EVENTOS!$D:$D,MATCH(SCORE!V$2&" "&SCORE!$D10,EVENTOS!$F:$F,0)),0) -> 0 | W10: =IFERROR(INDEX(EVENTOS!$D:$D,MATCH(SCORE!W$2&" "&SCORE!$D10,EVENTOS!$F:$F,0)),0) -> 0 | X10: =IFERROR(INDEX(EVENTOS!$D:$D,MATCH(SCORE!X$2&" "&SCORE!$D10,EVENTOS!$F:$F,0)),0) -> 0 | Y10: =SUMIFS(EVENTOS!$D:$D, EVENTOS!$B:$B, D10, EVENTOS!$E:$E, "*GirAlto*") -> 0 | Z10: =SUMIFS(EVENTOS!$D:$D, EVENTOS!$B:$B, D10, EVENTOS!$E:$E, "*GirMed*") -> 0 | AA10: =SUMIFS(EVENTOS!$D:$D, EVENTOS!$B:$B, D10, EVENTOS!$E:$E, "*GirBajo*") -> 3 | AB10: =IFERROR(INDEX(EVENTOS!$D:$D,MATCH(SCORE!AB$2&" "&SCORE!$D10,EVENTOS!$F:$F,0)),0) -> 0 | AC10: =IFERROR(INDEX(EVENTOS!$D:$D,MATCH(SCORE!AC$2&" "&SCORE!$D10,EVENTOS!$F:$F,0)),0) -> 0 | AD10: =IFERROR(INDEX(EVENTOS!$D:$D,MATCH(SCORE!AD$2&" "&SCORE!$D10,EVENTOS!$F:$F,0)),0) -> 19 | AE10: =((S10+V10+Y10+AB10)*50)+((T10+W10+Z10+AC10)*25)+((U10+X10+AA10+AD10)*5) -> 110 | AF10: =AE10/(G10*24)*100 -> 523.80952 | AG10: =IF(D10<>"",IF(AF10>=30000,5,ROUNDDOWN((((5-95)*(AF10-0))/(30000-0))+95,0)),"") -> 93 | AI10: =SUM(AG3:AG223) -> 7493 | AJ10: =AI10/87 -> 86.126437
B11: LIPU COLIMA | C11: 14111261 | D11: CASTILLO GRADILLA OSCAR EMILIO | E11: =VLOOKUP(D11,VIAJES!$D:$E,2,FALSE) -> 29 | F11: =VLOOKUP(D11,VIAJES!$D:$F,3,FALSE) -> 0.19305556 | G11: =VLOOKUP(D11,VIAJES!$D:$G,4,FALSE) -> 1.025 | H11: =VLOOKUP(D11,VIAJES!$D:$H,5,FALSE) -> 859.1 | S11: =IFERROR(INDEX(EVENTOS!$D:$D,MATCH(SCORE!S$2&" "&SCORE!$D11,EVENTOS!$F:$F,0)),0) -> 1 | T11: =IFERROR(INDEX(EVENTOS!$D:$D,MATCH(SCORE!T$2&" "&SCORE!$D11,EVENTOS!$F:$F,0)),0) -> 20 | U11: =IFERROR(INDEX(EVENTOS!$D:$D,MATCH(SCORE!U$2&" "&SCORE!$D11,EVENTOS!$F:$F,0)),0) -> 0 | V11: =IFERROR(INDEX(EVENTOS!$D:$D,MATCH(SCORE!V$2&" "&SCORE!$D11,EVENTOS!$F:$F,0)),0) -> 0 | W11: =IFERROR(INDEX(EVENTOS!$D:$D,MATCH(SCORE!W$2&" "&SCORE!$D11,EVENTOS!$F:$F,0)),0) -> 0 | X11: =IFERROR(INDEX(EVENTOS!$D:$D,MATCH(SCORE!X$2&" "&SCORE!$D11,EVENTOS!$F:$F,0)),0) -> 2 | Y11: =SUMIFS(EVENTOS!$D:$D, EVENTOS!$B:$B, D11, EVENTOS!$E:$E, "*GirAlto*") -> 1 | Z11: =SUMIFS(EVENTOS!$D:$D, EVENTOS!$B:$B, D11, EVENTOS!$E:$E, "*GirMed*") -> 1 | AA11: =SUMIFS(EVENTOS!$D:$D, EVENTOS!$B:$B, D11, EVENTOS!$E:$E, "*GirBajo*") -> 9 | AB11: =IFERROR(INDEX(EVENTOS!$D:$D,MATCH(SCORE!AB$2&" "&SCORE!$D11,EVENTOS!$F:$F,0)),0) -> 0 | AC11: =IFERROR(INDEX(EVENTOS!$D:$D,MATCH(SCORE!AC$2&" "&SCORE!$D11,EVENTOS!$F:$F,0)),0) -> 0 | AD11: =IFERROR(INDEX(EVENTOS!$D:$D,MATCH(SCORE!AD$2&" "&SCORE!$D11,EVENTOS!$F:$F,0)),0) -> 0 | AE11: =((S11+V11+Y11+AB11)*50)+((T11+W11+Z11+AC11)*25)+((U11+X11+AA11+AD11)*5) -> 680 | AF11: =AE11/(G11*24)*100 -> 2764.2276 | AG11: =IF(D11<>"",IF(AF11>=30000,5,ROUNDDOWN((((5-95)*(AF11-0))/(30000-0))+95,0)),"") -> 86
B12: LIPU COLIMA | C12: 14217288 | D12: CERNAS LOPEZ CLEMENTE MARTIN | E12: =VLOOKUP(D12,VIAJES!$D:$E,2,FALSE) -> 23 | F12: =VLOOKUP(D12,VIAJES!$D:$F,3,FALSE) -> 0.2375 | G12: =VLOOKUP(D12,VIAJES!$D:$G,4,FALSE) -> 0.49027778 | H12: =VLOOKUP(D12,VIAJES!$D:$H,5,FALSE) -> 330.05 | S12: =IFERROR(INDEX(EVENTOS!$D:$D,MATCH(SCORE!S$2&" "&SCORE!$D12,EVENTOS!$F:$F,0)),0) -> 8 | T12: =IFERROR(INDEX(EVENTOS!$D:$D,MATCH(SCORE!T$2&" "&SCORE!$D12,EVENTOS!$F:$F,0)),0) -> 0 | U12: =IFERROR(INDEX(EVENTOS!$D:$D,MATCH(SCORE!U$2&" "&SCORE!$D12,EVENTOS!$F:$F,0)),0) -> 0 | V12: =IFERROR(INDEX(EVENTOS!$D:$D,MATCH(SCORE!V$2&" "&SCORE!$D12,EVENTOS!$F:$F,0)),0) -> 2 | W12: =IFERROR(INDEX(EVENTOS!$D:$D,MATCH(SCORE!W$2&" "&SCORE!$D12,EVENTOS!$F:$F,0)),0) -> 0 | X12: =IFERROR(INDEX(EVENTOS!$D:$D,MATCH(SCORE!X$2&" "&SCORE!$D12,EVENTOS!$F:$F,0)),0) -> 0 | Y12: =SUMIFS(EVENTOS!$D:$D, EVENTOS!$B:$B, D12, EVENTOS!$E:$E, "*GirAlto*") -> 0 | Z12: =SUMIFS(EVENTOS!$D:$D, EVENTOS!$B:$B, D12, EVENTOS!$E:$E, "*GirMed*") -> 1 | AA12: =SUMIFS(EVENTOS!$D:$D, EVENTOS!$B:$B, D12, EVENTOS!$E:$E, "*GirBajo*") -> 4 | AB12: =IFERROR(INDEX(EVENTOS!$D:$D,MATCH(SCORE!AB$2&" "&SCORE!$D12,EVENTOS!$F:$F,0)),0) -> 0 | AC12: =IFERROR(INDEX(EVENTOS!$D:$D,MATCH(SCORE!AC$2&" "&SCORE!$D12,EVENTOS!$F:$F,0)),0) -> 0 | AD12: =IFERROR(INDEX(EVENTOS!$D:$D,MATCH(SCORE!AD$2&" "&SCORE!$D12,EVENTOS!$F:$F,0)),0) -> 1 | AE12: =((S12+V12+Y12+AB12)*50)+((T12+W12+Z12+AC12)*25)+((U12+X12+AA12+AD12)*5) -> 550 | AF12: =AE12/(G12*24)*100 -> 4674.221 | AG12: =IF(D12<>"",IF(AF12>=30000,5,ROUNDDOWN((((5-95)*(AF12-0))/(30000-0))+95,0)),"") -> 80
B13: LIPU COLIMA | C13: 14216383 | D13: CERVANTES CONTRERAS NICOLAS | E13: =VLOOKUP(D13,VIAJES!$D:$E,2,FALSE) -> 29 | F13: =VLOOKUP(D13,VIAJES!$D:$F,3,FALSE) -> 0.16736111 | G13: =VLOOKUP(D13,VIAJES!$D:$G,4,FALSE) -> 0.70833333 | H13: =VLOOKUP(D13,VIAJES!$D:$H,5,FALSE) -> 501.93 | S13: =IFERROR(INDEX(EVENTOS!$D:$D,MATCH(SCORE!S$2&" "&SCORE!$D13,EVENTOS!$F:$F,0)),0) -> 0 | T13: =IFERROR(INDEX(EVENTOS!$D:$D,MATCH(SCORE!T$2&" "&SCORE!$D13,EVENTOS!$F:$F,0)),0) -> 0 | U13: =IFERROR(INDEX(EVENTOS!$D:$D,MATCH(SCORE!U$2&" "&SCORE!$D13,EVENTOS!$F:$F,0)),0) -> 0 | V13: =IFERROR(INDEX(EVENTOS!$D:$D,MATCH(SCORE!V$2&" "&SCORE!$D13,EVENTOS!$F:$F,0)),0) -> 0 | W13: =IFERROR(INDEX(EVENTOS!$D:$D,MATCH(SCORE!W$2&" "&SCORE!$D13,EVENTOS!$F:$F,0)),0) -> 0 | X13: =IFERROR(INDEX(EVENTOS!$D:$D,MATCH(SCORE!X$2&" "&SCORE!$D13,EVENTOS!$F:$F,0)),0) -> 0 | Y13: =SUMIFS(EVENTOS!$D:$D, EVENTOS!$B:$B, D13, EVENTOS!$E:$E, "*GirAlto*") -> 0 | Z13: =SUMIFS(EVENTOS!$D:$D, EVENTOS!$B:$B, D13, EVENTOS!$E:$E, "*GirMed*") -> 1 | AA13: =SUMIFS(EVENTOS!$D:$D, EVENTOS!$B:$B, D13, EVENTOS!$E:$E, "*GirBajo*") -> 31 | AB13: =IFERROR(INDEX(EVENTOS!$D:$D,MATCH(SCORE!AB$2&" "&SCORE!$D13,EVENTOS!$F:$F,0)),0) -> 0 | AC13: =IFERROR(INDEX(EVENTOS!$D:$D,MATCH(SCORE!AC$2&" "&SCORE!$D13,EVENTOS!$F:$F,0)),0) -> 0 | AD13: =IFERROR(INDEX(EVENTOS!$D:$D,MATCH(SCORE!AD$2&" "&SCORE!$D13,EVENTOS!$F:$F,0)),0) -> 0 | AE13: =((S13+V13+Y13+AB13)*50)+((T13+W13+Z13+AC13)*25)+((U13+X13+AA13+AD13)*5) -> 180 | AF13: =AE13/(G13*24)*100 -> 1058.8235 | AG13: =IF(D13<>"",IF(AF13>=30000,5,ROUNDDOWN((((5-95)*(AF13-0))/(30000-0))+95,0)),"") -> 91
B14: LIPU COLIMA | C14: 14221929 | D14: CONTRERAS RUIZ JOSE GUADALUP | E14: =VLOOKUP(D14,VIAJES!$D:$E,2,FALSE) -> 20 | F14: =VLOOKUP(D14,VIAJES!$D:$F,3,FALSE) -> 0.082638889 | G14: =VLOOKUP(D14,VIAJES!$D:$G,4,FALSE) -> 0.55069444 | H14: =VLOOKUP(D14,VIAJES!$D:$H,5,FALSE) -> 554.67 | S14: =IFERROR(INDEX(EVENTOS!$D:$D,MATCH(SCORE!S$2&" "&SCORE!$D14,EVENTOS!$F:$F,0)),0) -> 1 | T14: =IFERROR(INDEX(EVENTOS!$D:$D,MATCH(SCORE!T$2&" "&SCORE!$D14,EVENTOS!$F:$F,0)),0) -> 0 | U14: =IFERROR(INDEX(EVENTOS!$D:$D,MATCH(SCORE!U$2&" "&SCORE!$D14,EVENTOS!$F:$F,0)),0) -> 0 | V14: =IFERROR(INDEX(EVENTOS!$D:$D,MATCH(SCORE!V$2&" "&SCORE!$D14,EVENTOS!$F:$F,0)),0) -> 0 | W14: =IFERROR(INDEX(EVENTOS!$D:$D,MATCH(SCORE!W$2&" "&SCORE!$D14,EVENTOS!$F:$F,0)),0) -> 1 | X14: =IFERROR(INDEX(EVENTOS!$D:$D,MATCH(SCORE!X$2&" "&SCORE!$D14,EVENTOS!$F:$F,0)),0) -> 1 | Y14: =SUMIFS(EVENTOS!$D:$D, EVENTOS!$B:$B, D14, EVENTOS!$E:$E, "*GirAlto*") -> 0 | Z14: =SUMIFS(EVENTOS!$D:$D, EVENTOS!$B:$B, D14, EVENTOS!$E:$E, "*GirMed*") -> 1 | AA14: =SUMIFS(EVENTOS!$D:$D, EVENTOS!$B:$B, D14, EVENTOS!$E:$E, "*GirBajo*") -> 2 | AB14: =IFERROR(INDEX(EVENTOS!$D:$D,MATCH(SCORE!AB$2&" "&SCORE!$D14,EVENTOS!$F:$F,0)),0) -> 0 | AC14: =IFERROR(INDEX(EVENTOS!$D:$D,MATCH(SCORE!AC$2&" "&SCORE!$D14,EVENTOS!$F:$F,0)),0) -> 0 | AD14: =IFERROR(INDEX(EVENTOS!$D:$D,MATCH(SCORE!AD$2&" "&SCORE!$D14,EVENTOS!$F:$F,0)),0) -> 1 | AE14: =((S14+V14+Y14+AB14)*50)+((T14+W14+Z14+AC14)*25)+((U14+X14+AA14+AD14)*5) -> 120 | AF14: =AE14/(G14*24)*100 -> 907.94451 | AG14: =IF(D14<>"",IF(AF14>=30000,5,ROUNDDOWN((((5-95)*(AF14-0))/(30000-0))+95,0)),"") -> 92
B15: LIPU COLIMA | C15: 14219642 | D15: DAMIAN LOPEZ RIGOBERTO SUSANO | E15: =VLOOKUP(D15,VIAJES!$D:$E,2,FALSE) -> 57 | F15: =VLOOKUP(D15,VIAJES!$D:$F,3,FALSE) -> 0.36180556 | G15: =VLOOKUP(D15,VIAJES!$D:$G,4,FALSE) -> 1.2923611 | H15: =VLOOKUP(D15,VIAJES!$D:$H,5,FALSE) -> 1067.57 | S15: =IFERROR(INDEX(EVENTOS!$D:$D,MATCH(SCORE!S$2&" "&SCORE!$D15,EVENTOS!$F:$F,0)),0) -> 5 | T15: =IFERROR(INDEX(EVENTOS!$D:$D,MATCH(SCORE!T$2&" "&SCORE!$D15,EVENTOS!$F:$F,0)),0) -> 0 | U15: =IFERROR(INDEX(EVENTOS!$D:$D,MATCH(SCORE!U$2&" "&SCORE!$D15,EVENTOS!$F:$F,0)),0) -> 0 | V15: =IFERROR(INDEX(EVENTOS!$D:$D,MATCH(SCORE!V$2&" "&SCORE!$D15,EVENTOS!$F:$F,0)),0) -> 0 | W15: =IFERROR(INDEX(EVENTOS!$D:$D,MATCH(SCORE!W$2&" "&SCORE!$D15,EVENTOS!$F:$F,0)),0) -> 0 | X15: =IFERROR(INDEX(EVENTOS!$D:$D,MATCH(SCORE!X$2&" "&SCORE!$D15,EVENTOS!$F:$F,0)),0) -> 0 | Y15: =SUMIFS(EVENTOS!$D:$D, EVENTOS!$B:$B, D15, EVENTOS!$E:$E, "*GirAlto*") -> 0 | Z15: =SUMIFS(EVENTOS!$D:$D, EVENTOS!$B:$B, D15, EVENTOS!$E:$E, "*GirMed*") -> 14 | AA15: =SUMIFS(EVENTOS!$D:$D, EVENTOS!$B:$B, D15, EVENTOS!$E:$E, "*GirBajo*") -> 108 | AB15: =IFERROR(INDEX(EVENTOS!$D:$D,MATCH(SCORE!AB$2&" "&SCORE!$D15,EVENTOS!$F:$F,0)),0) -> 0 | AC15: =IFERROR(INDEX(EVENTOS!$D:$D,MATCH(SCORE!AC$2&" "&SCORE!$D15,EVENTOS!$F:$F,0)),0) -> 0 | AD15: =IFERROR(INDEX(EVENTOS!$D:$D,MATCH(SCORE!AD$2&" "&SCORE!$D15,EVENTOS!$F:$F,0)),0) -> 19 | AE15: =((S15+V15+Y15+AB15)*50)+((T15+W15+Z15+AC15)*25)+((U15+X15+AA15+AD15)*5) -> 1235 | AF15: =AE15/(G15*24)*100 -> 3981.7303 | AG15: =IF(D15<>"",IF(AF15>=30000,5,ROUNDDOWN((((5-95)*(AF15-0))/(30000-0))+95,0)),"") -> 83
B16: LIPU COLIMA | C16: 14106275 | D16: DE ANDA MARTINEZ LUIS HUMBERTO | E16: =VLOOKUP(D16,VIAJES!$D:$E,2,FALSE) -> 42 | F16: =VLOOKUP(D16,VIAJES!$D:$F,3,FALSE) -> 0.2875 | G16: =VLOOKUP(D16,VIAJES!$D:$G,4,FALSE) -> 0.64930556 | H16: =VLOOKUP(D16,VIAJES!$D:$H,5,FALSE) -> 302.9 | S16: =IFERROR(INDEX(EVENTOS!$D:$D,MATCH(SCORE!S$2&" "&SCORE!$D16,EVENTOS!$F:$F,0)),0) -> 0 | T16: =IFERROR(INDEX(EVENTOS!$D:$D,MATCH(SCORE!T$2&" "&SCORE!$D16,EVENTOS!$F:$F,0)),0) -> 0 | U16: =IFERROR(INDEX(EVENTOS!$D:$D,MATCH(SCORE!U$2&" "&SCORE!$D16,EVENTOS!$F:$F,0)),0) -> 0 | V16: =IFERROR(INDEX(EVENTOS!$D:$D,MATCH(SCORE!V$2&" "&SCORE!$D16,EVENTOS!$F:$F,0)),0) -> 0 | W16: =IFERROR(INDEX(EVENTOS!$D:$D,MATCH(SCORE!W$2&" "&SCORE!$D16,EVENTOS!$F:$F,0)),0) -> 0 | X16: =IFERROR(INDEX(EVENTOS!$D:$D,MATCH(SCORE!X$2&" "&SCORE!$D16,EVENTOS!$F:$F,0)),0) -> 0 | Y16: =SUMIFS(EVENTOS!$D:$D, EVENTOS!$B:$B, D16, EVENTOS!$E:$E, "*GirAlto*") -> 0 | Z16: =SUMIFS(EVENTOS!$D:$D, EVENTOS!$B:$B, D16, EVENTOS!$E:$E, "*GirMed*") -> 0 | AA16: =SUMIFS(EVENTOS!$D:$D, EVENTOS!$B:$B, D16, EVENTOS!$E:$E, "*GirBajo*") -> 0 | AB16: =IFERROR(INDEX(EVENTOS!$D:$D,MATCH(SCORE!AB$2&" "&SCORE!$D16,EVENTOS!$F:$F,0)),0) -> 0 | AC16: =IFERROR(INDEX(EVENTOS!$D:$D,MATCH(SCORE!AC$2&" "&SCORE!$D16,EVENTOS!$F:$F,0)),0) -> 0 | AD16: =IFERROR(INDEX(EVENTOS!$D:$D,MATCH(SCORE!AD$2&" "&SCORE!$D16,EVENTOS!$F:$F,0)),0) -> 0 | AE16: =((S16+V16+Y16+AB16)*50)+((T16+W16+Z16+AC16)*25)+((U16+X16+AA16+AD16)*5) -> 0 | AF16: =AE16/(G16*24)*100 -> 0 | AG16: =IF(D16<>"",IF(AF16>=30000,5,ROUNDDOWN((((5-95)*(AF16-0))/(30000-0))+95,0)),"") -> 95
B17: LIPU COLIMA | C17: 14222269 | D17: DURAN RAMIREZ JUAN CARLOS | E17: =VLOOKUP(D17,VIAJES!$D:$E,2,FALSE) -> 30 | F17: =VLOOKUP(D17,VIAJES!$D:$F,3,FALSE) -> 0.33819444 | G17: =VLOOKUP(D17,VIAJES!$D:$G,4,FALSE) -> 1.3305556 | H17: =VLOOKUP(D17,VIAJES!$D:$H,5,FALSE) -> 706.44 | S17: =IFERROR(INDEX(EVENTOS!$D:$D,MATCH(SCORE!S$2&" "&SCORE!$D17,EVENTOS!$F:$F,0)),0) -> 0 | T17: =IFERROR(INDEX(EVENTOS!$D:$D,MATCH(SCORE!T$2&" "&SCORE!$D17,EVENTOS!$F:$F,0)),0) -> 0 | U17: =IFERROR(INDEX(EVENTOS!$D:$D,MATCH(SCORE!U$2&" "&SCORE!$D17,EVENTOS!$F:$F,0)),0) -> 0 | V17: =IFERROR(INDEX(EVENTOS!$D:$D,MATCH(SCORE!V$2&" "&SCORE!$D17,EVENTOS!$F:$F,0)),0) -> 0 | W17: =IFERROR(INDEX(EVENTOS!$D:$D,MATCH(SCORE!W$2&" "&SCORE!$D17,EVENTOS!$F:$F,0)),0) -> 0 | X17: =IFERROR(INDEX(EVENTOS!$D:$D,MATCH(SCORE!X$2&" "&SCORE!$D17,EVENTOS!$F:$F,0)),0) -> 0 | Y17: =SUMIFS(EVENTOS!$D:$D, EVENTOS!$B:$B, D17, EVENTOS!$E:$E, "*GirAlto*") -> 1 | Z17: =SUMIFS(EVENTOS!$D:$D, EVENTOS!$B:$B, D17, EVENTOS!$E:$E, "*GirMed*") -> 5 | AA17: =SUMIFS(EVENTOS!$D:$D, EVENTOS!$B:$B, D17, EVENTOS!$E:$E, "*GirBajo*") -> 19 | AB17: =IFERROR(INDEX(EVENTOS!$D:$D,MATCH(SCORE!AB$2&" "&SCORE!$D17,EVENTOS!$F:$F,0)),0) -> 0 | AC17: =IFERROR(INDEX(EVENTOS!$D:$D,MATCH(SCORE!AC$2&" "&SCORE!$D17,EVENTOS!$F:$F,0)),0) -> 0 | AD17: =IFERROR(INDEX(EVENTOS!$D:$D,MATCH(SCORE!AD$2&" "&SCORE!$D17,EVENTOS!$F:$F,0)),0) -> 0 | AE17: =((S17+V17+Y17+AB17)*50)+((T17+W17+Z17+AC17)*25)+((U17+X17+AA17+AD17)*5) -> 270 | AF17: =AE17/(G17*24)*100 -> 845.51148 | AG17: =IF(D17<>"",IF(AF17>=30000,5,ROUNDDOWN((((5-95)*(AF17-0))/(30000-0))+95,0)),"") -> 92
B18: LIPU COLIMA | C18: 14220597 | D18: ESCOTO RAMIREZ JOSE LUIS | E18: =VLOOKUP(D18,VIAJES!$D:$E,2,FALSE) -> 50 | F18: =VLOOKUP(D18,VIAJES!$D:$F,3,FALSE) -> 0.34513889 | G18: =VLOOKUP(D18,VIAJES!$D:$G,4,FALSE) -> 1.7368056 | H18: =VLOOKUP(D18,VIAJES!$D:$H,5,FALSE) -> 1462.42 | S18: =IFERROR(INDEX(EVENTOS!$D:$D,MATCH(SCORE!S$2&" "&SCORE!$D18,EVENTOS!$F:$F,0)),0) -> 1 | T18: =IFERROR(INDEX(EVENTOS!$D:$D,MATCH(SCORE!T$2&" "&SCORE!$D18,EVENTOS!$F:$F,0)),0) -> 0 | U18: =IFERROR(INDEX(EVENTOS!$D:$D,MATCH(SCORE!U$2&" "&SCORE!$D18,EVENTOS!$F:$F,0)),0) -> 0 | V18: =IFERROR(INDEX(EVENTOS!$D:$D,MATCH(SCORE!V$2&" "&SCORE!$D18,EVENTOS!$F:$F,0)),0) -> 0 | W18: =IFERROR(INDEX(EVENTOS!$D:$D,MATCH(SCORE!W$2&" "&SCORE!$D18,EVENTOS!$F:$F,0)),0) -> 0 | X18: =IFERROR(INDEX(EVENTOS!$D:$D,MATCH(SCORE!X$2&" "&SCORE!$D18,EVENTOS!$F:$F,0)),0) -> 0 | Y18: =SUMIFS(EVENTOS!$D:$D, EVENTOS!$B:$B, D18, EVENTOS!$E:$E, "*GirAlto*") -> 0 | Z18: =SUMIFS(EVENTOS!$D:$D, EVENTOS!$B:$B, D18, EVENTOS!$E:$E, "*GirMed*") -> 0 | AA18: =SUMIFS(EVENTOS!$D:$D, EVENTOS!$B:$B, D18, EVENTOS!$E:$E, "*GirBajo*") -> 15 | AB18: =IFERROR(INDEX(EVENTOS!$D:$D,MATCH(SCORE!AB$2&" "&SCORE!$D18,EVENTOS!$F:$F,0)),0) -> 0 | AC18: =IFERROR(INDEX(EVENTOS!$D:$D,MATCH(SCORE!AC$2&" "&SCORE!$D18,EVENTOS!$F:$F,0)),0) -> 0 | AD18: =IFERROR(INDEX(EVENTOS!$D:$D,MATCH(SCORE!AD$2&" "&SCORE!$D18,EVENTOS!$F:$F,0)),0) -> 8 | AE18: =((S18+V18+Y18+AB18)*50)+((T18+W18+Z18+AC18)*25)+((U18+X18+AA18+AD18)*5) -> 165 | AF18: =AE18/(G18*24)*100 -> 395.84166 | AG18: =IF(D18<>"",IF(AF18>=30000,5,ROUNDDOWN((((5-95)*(AF18-0))/(30000-0))+95,0)),"") -> 93
B19: LIPU COLIMA | C19: 14222352 | D19: ESPINOSA CEBALLOS EDGAR ABRA | E19: =VLOOKUP(D19,VIAJES!$D:$E,2,FALSE) -> 85 | F19: =VLOOKUP(D19,VIAJES!$D:$F,3,FALSE) -> 0.60902778 | G19: =VLOOKUP(D19,VIAJES!$D:$G,4,FALSE) -> 1.2402778 | H19: =VLOOKUP(D19,VIAJES!$D:$H,5,FALSE) -> 625.32 | S19: =IFERROR(INDEX(EVENTOS!$D:$D,MATCH(SCORE!S$2&" "&SCORE!$D19,EVENTOS!$F:$F,0)),0) -> 0 | T19: =IFERROR(INDEX(EVENTOS!$D:$D,MATCH(SCORE!T$2&" "&SCORE!$D19,EVENTOS!$F:$F,0)),0) -> 0 | U19: =IFERROR(INDEX(EVENTOS!$D:$D,MATCH(SCORE!U$2&" "&SCORE!$D19,EVENTOS!$F:$F,0)),0) -> 0 | V19: =IFERROR(INDEX(EVENTOS!$D:$D,MATCH(SCORE!V$2&" "&SCORE!$D19,EVENTOS!$F:$F,0)),0) -> 0 | W19: =IFERROR(INDEX(EVENTOS!$D:$D,MATCH(SCORE!W$2&" "&SCORE!$D19,EVENTOS!$F:$F,0)),0) -> 0 | X19: =IFERROR(INDEX(EVENTOS!$D:$D,MATCH(SCORE!X$2&" "&SCORE!$D19,EVENTOS!$F:$F,0)),0) -> 0 | Y19: =SUMIFS(EVENTOS!$D:$D, EVENTOS!$B:$B, D19, EVENTOS!$E:$E, "*GirAlto*") -> 0 | Z19: =SUMIFS(EVENTOS!$D:$D, EVENTOS!$B:$B, D19, EVENTOS!$E:$E, "*GirMed*") -> 0 | AA19: =SUMIFS(EVENTOS!$D:$D, EVENTOS!$B:$B, D19, EVENTOS!$E:$E, "*GirBajo*") -> 1 | AB19: =IFERROR(INDEX(EVENTOS!$D:$D,MATCH(SCORE!AB$2&" "&SCORE!$D19,EVENTOS!$F:$F,0)),0) -> 0 | AC19: =IFERROR(INDEX(EVENTOS!$D:$D,MATCH(SCORE!AC$2&" "&SCORE!$D19,EVENTOS!$F:$F,0)),0) -> 1 | AD19: =IFERROR(INDEX(EVENTOS!$D:$D,MATCH(SCORE!AD$2&" "&SCORE!$D19,EVENTOS!$F:$F,0)),0) -> 4 | AE19: =((S19+V19+Y19+AB19)*50)+((T19+W19+Z19+AC19)*25)+((U19+X19+AA19+AD19)*5) -> 50 | AF19: =AE19/(G19*24)*100 -> 167.97312 | AG19: =IF(D19<>"",IF(AF19>=30000,5,ROUNDDOWN((((5-95)*(AF19-0))/(30000-0))+95,0)),"") -> 94
B20: LIPU COLIMA | C20: 14218655 | D20: ESTRADA GONZALEZ EDGAR EFREN | E20: =VLOOKUP(D20,VIAJES!$D:$E,2,FALSE) -> 24 | F20: =VLOOKUP(D20,VIAJES!$D:$F,3,FALSE) -> 0.24444444 | G20: =VLOOKUP(D20,VIAJES!$D:$G,4,FALSE) -> 0.54027778 | H20: =VLOOKUP(D20,VIAJES!$D:$H,5,FALSE) -> 414.15 | S20: =IFERROR(INDEX(EVENTOS!$D:$D,MATCH(SCORE!S$2&" "&SCORE!$D20,EVENTOS!$F:$F,0)),0) -> 0 | T20: =IFERROR(INDEX(EVENTOS!$D:$D,MATCH(SCORE!T$2&" "&SCORE!$D20,EVENTOS!$F:$F,0)),0) -> 0 | U20: =IFERROR(INDEX(EVENTOS!$D:$D,MATCH(SCORE!U$2&" "&SCORE!$D20,EVENTOS!$F:$F,0)),0) -> 0 | V20: =IFERROR(INDEX(EVENTOS!$D:$D,MATCH(SCORE!V$2&" "&SCORE!$D20,EVENTOS!$F:$F,0)),0) -> 0 | W20: =IFERROR(INDEX(EVENTOS!$D:$D,MATCH(SCORE!W$2&" "&SCORE!$D20,EVENTOS!$F:$F,0)),0) -> 6 | X20: =IFERROR(INDEX(EVENTOS!$D:$D,MATCH(SCORE!X$2&" "&SCORE!$D20,EVENTOS!$F:$F,0)),0) -> 5 | Y20: =SUMIFS(EVENTOS!$D:$D, EVENTOS!$B:$B, D20, EVENTOS!$E:$E, "*GirAlto*") -> 0 | Z20: =SUMIFS(EVENTOS!$D:$D, EVENTOS!$B:$B, D20, EVENTOS!$E:$E, "*GirMed*") -> 3 | AA20: =SUMIFS(EVENTOS!$D:$D, EVENTOS!$B:$B, D20, EVENTOS!$E:$E, "*GirBajo*") -> 21 | AB20: =IFERROR(INDEX(EVENTOS!$D:$D,MATCH(SCORE!AB$2&" "&SCORE!$D20,EVENTOS!$F:$F,0)),0) -> 0 | AC20: =IFERROR(INDEX(EVENTOS!$D:$D,MATCH(SCORE!AC$2&" "&SCORE!$D20,EVENTOS!$F:$F,0)),0) -> 0 | AD20: =IFERROR(INDEX(EVENTOS!$D:$D,MATCH(SCORE!AD$2&" "&SCORE!$D20,EVENTOS!$F:$F,0)),0) -> 4 | AE20: =((S20+V20+Y20+AB20)*50)+((T20+W20+Z20+AC20)*25)+((U20+X20+AA20+AD20)*5) -> 375 | AF20: =AE20/(G20*24)*100 -> 2892.0308 | AG20: =IF(D20<>"",IF(AF20>=30000,5,ROUNDDOWN((((5-95)*(AF20-0))/(30000-0))+95,0)),"") -> 86
B21: LIPU COLIMA | C21: 14217918 | D21: FRANCO GOMEZ JORGE ALBERTO | E21: =VLOOKUP(D21,VIAJES!$D:$E,2,FALSE) -> 30 | F21: =VLOOKUP(D21,VIAJES!$D:$F,3,FALSE) -> 0.32638889 | G21: =VLOOKUP(D21,VIAJES!$D:$G,4,FALSE) -> 1.2465278 | H21: =VLOOKUP(D21,VIAJES!$D:$H,5,FALSE) -> 1191.66 | S21: =IFERROR(INDEX(EVENTOS!$D:$D,MATCH(SCORE!S$2&" "&SCORE!$D21,EVENTOS!$F:$F,0)),0) -> 2 | T21: =IFERROR(INDEX(EVENTOS!$D:$D,MATCH(SCORE!T$2&" "&SCORE!$D21,EVENTOS!$F:$F,0)),0) -> 0 | U21: =IFERROR(INDEX(EVENTOS!$D:$D,MATCH(SCORE!U$2&" "&SCORE!$D21,EVENTOS!$F:$F,0)),0) -> 0 | V21: =IFERROR(INDEX(EVENTOS!$D:$D,MATCH(SCORE!V$2&" "&SCORE!$D21,EVENTOS!$F:$F,0)),0) -> 0 | W21: =IFERROR(INDEX(EVENTOS!$D:$D,MATCH(SCORE!W$2&" "&SCORE!$D21,EVENTOS!$F:$F,0)),0) -> 0 | X21: =IFERROR(INDEX(EVENTOS!$D:$D,MATCH(SCORE!X$2&" "&SCORE!$D21,EVENTOS!$F:$F,0)),0) -> 0 | Y21: =SUMIFS(EVENTOS!$D:$D, EVENTOS!$B:$B, D21, EVENTOS!$E:$E, "*GirAlto*") -> 0 | Z21: =SUMIFS(EVENTOS!$D:$D, EVENTOS!$B:$B, D21, EVENTOS!$E:$E, "*GirMed*") -> 1 | AA21: =SUMIFS(EVENTOS!$D:$D, EVENTOS!$B:$B, D21, EVENTOS!$E:$E, "*GirBajo*") -> 6 | AB21: =IFERROR(INDEX(EVENTOS!$D:$D,MATCH(SCORE!AB$2&" "&SCORE!$D21,EVENTOS!$F:$F,0)),0) -> 0 | AC21: =IFERROR(INDEX(EVENTOS!$D:$D,MATCH(SCORE!AC$2&" "&SCORE!$D21,EVENTOS!$F:$F,0)),0) -> 0 | AD21: =IFERROR(INDEX(EVENTOS!$D:$D,MATCH(SCORE!AD$2&" "&SCORE!$D21,EVENTOS!$F:$F,0)),0) -> 91 | AE21: =((S21+V21+Y21+AB21)*50)+((T21+W21+Z21+AC21)*25)+((U21+X21+AA21+AD21)*5) -> 610 | AF21: =AE21/(G21*24)*100 -> 2038.9972 | AG21: =IF(D21<>"",IF(AF21>=30000,5,ROUNDDOWN((((5-95)*(AF21-0))/(30000-0))+95,0)),"") -> 88
B22: LIPU COLIMA | C22: 14220598 | D22: FUENTES CHAVEZ PEDRO OMAR | E22: =VLOOKUP(D22,VIAJES!$D:$E,2,FALSE) -> 24 | F22: =VLOOKUP(D22,VIAJES!$D:$F,3,FALSE) -> 0.15486111 | G22: =VLOOKUP(D22,VIAJES!$D:$G,4,FALSE) -> 0.71458333 | H22: =VLOOKUP(D22,VIAJES!$D:$H,5,FALSE) -> 689.59 | S22: =IFERROR(INDEX(EVENTOS!$D:$D,MATCH(SCORE!S$2&" "&SCORE!$D22,EVENTOS!$F:$F,0)),0) -> 1 | T22: =IFERROR(INDEX(EVENTOS!$D:$D,MATCH(SCORE!T$2&" "&SCORE!$D22,EVENTOS!$F:$F,0)),0) -> 0 | U22: =IFERROR(INDEX(EVENTOS!$D:$D,MATCH(SCORE!U$2&" "&SCORE!$D22,EVENTOS!$F:$F,0)),0) -> 0 | V22: =IFERROR(INDEX(EVENTOS!$D:$D,MATCH(SCORE!V$2&" "&SCORE!$D22,EVENTOS!$F:$F,0)),0) -> 0 | W22: =IFERROR(INDEX(EVENTOS!$D:$D,MATCH(SCORE!W$2&" "&SCORE!$D22,EVENTOS!$F:$F,0)),0) -> 0 | X22: =IFERROR(INDEX(EVENTOS!$D:$D,MATCH(SCORE!X$2&" "&SCORE!$D22,EVENTOS!$F:$F,0)),0) -> 1 | Y22: =SUMIFS(EVENTOS!$D:$D, EVENTOS!$B:$B, D22, EVENTOS!$E:$E, "*GirAlto*") -> 0 | Z22: =SUMIFS(EVENTOS!$D:$D, EVENTOS!$B:$B, D22, EVENTOS!$E:$E, "*GirMed*") -> 0 | AA22: =SUMIFS(EVENTOS!$D:$D, EVENTOS!$B:$B, D22, EVENTOS!$E:$E, "*GirBajo*") -> 5 | AB22: =IFERROR(INDEX(EVENTOS!$D:$D,MATCH(SCORE!AB$2&" "&SCORE!$D22,EVENTOS!$F:$F,0)),0) -> 0 | AC22: =IFERROR(INDEX(EVENTOS!$D:$D,MATCH(SCORE!AC$2&" "&SCORE!$D22,EVENTOS!$F:$F,0)),0) -> 0 | AD22: =IFERROR(INDEX(EVENTOS!$D:$D,MATCH(SCORE!AD$2&" "&SCORE!$D22,EVENTOS!$F:$F,0)),0) -> 1 | AE22: =((S22+V22+Y22+AB22)*50)+((T22+W22+Z22+AC22)*25)+((U22+X22+AA22+AD22)*5) -> 85 | AF22: =AE22/(G22*24)*100 -> 495.62682 | AG22: =IF(D22<>"",IF(AF22>=30000,5,ROUNDDOWN((((5-95)*(AF22-0))/(30000-0))+95,0)),"") -> 93
... B45: LIPU COLIMA | C45: 14222163 | D45: OCHOA GUERRERO EDGAR JESUS | E45: =VLOOKUP(D45,VIAJES!$D:$E,2,FALSE) -> 47 | F45: =VLOOKUP(D45,VIAJES!$D:$F,3,FALSE) -> 0.23194444 | G45: =VLOOKUP(D45,VIAJES!$D:$G,4,FALSE) -> 0.91805556 | H45: =VLOOKUP(D45,VIAJES!$D:$H,5,FALSE) -> 762.29 | S45: =IFERROR(INDEX(EVENTOS!$D:$D,MATCH(SCORE!S$2&" "&SCORE!$D45,EVENTOS!$F:$F,0)),0) -> 1 | T45: =IFERROR(INDEX(EVENTOS!$D:$D,MATCH(SCORE!T$2&" "&SCORE!$D45,EVENTOS!$F:$F,0)),0) -> 13 | U45: =IFERROR(INDEX(EVENTOS!$D:$D,MATCH(SCORE!U$2&" "&SCORE!$D45,EVENTOS!$F:$F,0)),0) -> 0 | V45: =IFERROR(INDEX(EVENTOS!$D:$D,MATCH(SCORE!V$2&" "&SCORE!$D45,EVENTOS!$F:$F,0)),0) -> 0 | W45: =IFERROR(INDEX(EVENTOS!$D:$D,MATCH(SCORE!W$2&" "&SCORE!$D45,EVENTOS!$F:$F,0)),0) -> 1 | X45: =IFERROR(INDEX(EVENTOS!$D:$D,MATCH(SCORE!X$2&" "&SCORE!$D45,EVENTOS!$F:$F,0)),0) -> 3 | Y45: =SUMIFS(EVENTOS!$D:$D, EVENTOS!$B:$B, D45, EVENTOS!$E:$E, "*GirAlto*") -> 0 | Z45: =SUMIFS(EVENTOS!$D:$D, EVENTOS!$B:$B, D45, EVENTOS!$E:$E, "*GirMed*") -> 6 | AA45: =SUMIFS(EVENTOS!$D:$D, EVENTOS!$B:$B, D45, EVENTOS!$E:$E, "*GirBajo*") -> 37 | AB45: =IFERROR(INDEX(EVENTOS!$D:$D,MATCH(SCORE!AB$2&" "&SCORE!$D45,EVENTOS!$F:$F,0)),0) -> 0 | AC45: =IFERROR(INDEX(EVENTOS!$D:$D,MATCH(SCORE!AC$2&" "&SCORE!$D45,EVENTOS!$F:$F,0)),0) -> 0 | AD45: =IFERROR(INDEX(EVENTOS!$D:$D,MATCH(SCORE!AD$2&" "&SCORE!$D45,EVENTOS!$F:$F,0)),0) -> 1 | AE45: =((S45+V45+Y45+AB45)*50)+((T45+W45+Z45+AC45)*25)+((U45+X45+AA45+AD45)*5) -> 755 | AF45: =AE45/(G45*24)*100 -> 3426.6263 | AG45: =IF(D45<>"",IF(AF45>=30000,5,ROUNDDOWN((((5-95)*(AF45-0))/(30000-0))+95,0)),"") -> 84
B46: LIPU COLIMA | D46: P.CHAVEZ PAREDES JUAN MANUEL | E46: =VLOOKUP(D46,VIAJES!$D:$E,2,FALSE) -> 3 | F46: =VLOOKUP(D46,VIAJES!$D:$F,3,FALSE) -> 0.0027777778 | G46: =VLOOKUP(D46,VIAJES!$D:$G,4,FALSE) -> 0.034027778 | H46: =VLOOKUP(D46,VIAJES!$D:$H,5,FALSE) -> 47.52 | S46: =IFERROR(INDEX(EVENTOS!$D:$D,MATCH(SCORE!S$2&" "&SCORE!$D46,EVENTOS!$F:$F,0)),0) -> 0 | T46: =IFERROR(INDEX(EVENTOS!$D:$D,MATCH(SCORE!T$2&" "&SCORE!$D46,EVENTOS!$F:$F,0)),0) -> 0 | U46: =IFERROR(INDEX(EVENTOS!$D:$D,MATCH(SCORE!U$2&" "&SCORE!$D46,EVENTOS!$F:$F,0)),0) -> 0 | V46: =IFERROR(INDEX(EVENTOS!$D:$D,MATCH(SCORE!V$2&" "&SCORE!$D46,EVENTOS!$F:$F,0)),0) -> 0 | W46: =IFERROR(INDEX(EVENTOS!$D:$D,MATCH(SCORE!W$2&" "&SCORE!$D46,EVENTOS!$F:$F,0)),0) -> 0 | X46: =IFERROR(INDEX(EVENTOS!$D:$D,MATCH(SCORE!X$2&" "&SCORE!$D46,EVENTOS!$F:$F,0)),0) -> 0 | Y46: =SUMIFS(EVENTOS!$D:$D, EVENTOS!$B:$B, D46, EVENTOS!$E:$E, "*GirAlto*") -> 0 | Z46: =SUMIFS(EVENTOS!$D:$D, EVENTOS!$B:$B, D46, EVENTOS!$E:$E, "*GirMed*") -> 1 | AA46: =SUMIFS(EVENTOS!$D:$D, EVENTOS!$B:$B, D46, EVENTOS!$E:$E, "*GirBajo*") -> 3 | AB46: =IFERROR(INDEX(EVENTOS!$D:$D,MATCH(SCORE!AB$2&" "&SCORE!$D46,EVENTOS!$F:$F,0)),0) -> 0 | AC46: =IFERROR(INDEX(EVENTOS!$D:$D,MATCH(SCORE!AC$2&" "&SCORE!$D46,EVENTOS!$F:$F,0)),0) -> 1 | AD46: =IFERROR(INDEX(EVENTOS!$D:$D,MATCH(SCORE!AD$2&" "&SCORE!$D46,EVENTOS!$F:$F,0)),0) -> 10 | AE46: =((S46+V46+Y46+AB46)*50)+((T46+W46+Z46+AC46)*25)+((U46+X46+AA46+AD46)*5) -> 115 | AF46: =AE46/(G46*24)*100 -> 14081.633 | AG46: =IF(D46<>"",IF(AF46>=30000,5,ROUNDDOWN((((5-95)*(AF46-0))/(30000-0))+95,0)),"") -> 52
B47: LIPU COLIMA | D47: P.FARIAS BARAJAS DIEGO FAVIAN | E47: =VLOOKUP(D47,VIAJES!$D:$E,2,FALSE) -> 2 | F47: =VLOOKUP(D47,VIAJES!$D:$F,3,FALSE) -> 0.00625 | G47: =VLOOKUP(D47,VIAJES!$D:$G,4,FALSE) -> 0.048611111 | H47: =VLOOKUP(D47,VIAJES!$D:$H,5,FALSE) -> 54.55 | S47: =IFERROR(INDEX(EVENTOS!$D:$D,MATCH(SCORE!S$2&" "&SCORE!$D47,EVENTOS!$F:$F,0)),0) -> 2 | T47: =IFERROR(INDEX(EVENTOS!$D:$D,MATCH(SCORE!T$2&" "&SCORE!$D47,EVENTOS!$F:$F,0)),0) -> 0 | U47: =IFERROR(INDEX(EVENTOS!$D:$D,MATCH(SCORE!U$2&" "&SCORE!$D47,EVENTOS!$F:$F,0)),0) -> 0 | V47: =IFERROR(INDEX(EVENTOS!$D:$D,MATCH(SCORE!V$2&" "&SCORE!$D47,EVENTOS!$F:$F,0)),0) -> 0 | W47: =IFERROR(INDEX(EVENTOS!$D:$D,MATCH(SCORE!W$2&" "&SCORE!$D47,EVENTOS!$F:$F,0)),0) -> 0 | X47: =IFERROR(INDEX(EVENTOS!$D:$D,MATCH(SCORE!X$2&" "&SCORE!$D47,EVENTOS!$F:$F,0)),0) -> 0 | Y47: =SUMIFS(EVENTOS!$D:$D, EVENTOS!$B:$B, D47, EVENTOS!$E:$E, "*GirAlto*") -> 0 | Z47: =SUMIFS(EVENTOS!$D:$D, EVENTOS!$B:$B, D47, EVENTOS!$E:$E, "*GirMed*") -> 0 | AA47: =SUMIFS(EVENTOS!$D:$D, EVENTOS!$B:$B, D47, EVENTOS!$E:$E, "*GirBajo*") -> 0 | AB47: =IFERROR(INDEX(EVENTOS!$D:$D,MATCH(SCORE!AB$2&" "&SCORE!$D47,EVENTOS!$F:$F,0)),0) -> 0 | AC47: =IFERROR(INDEX(EVENTOS!$D:$D,MATCH(SCORE!AC$2&" "&SCORE!$D47,EVENTOS!$F:$F,0)),0) -> 0 | AD47: =IFERROR(INDEX(EVENTOS!$D:$D,MATCH(SCORE!AD$2&" "&SCORE!$D47,EVENTOS!$F:$F,0)),0) -> 4 | AE47: =((S47+V47+Y47+AB47)*50)+((T47+W47+Z47+AC47)*25)+((U47+X47+AA47+AD47)*5) -> 120 | AF47: =AE47/(G47*24)*100 -> 10285.714 | AG47: =IF(D47<>"",IF(AF47>=30000,5,ROUNDDOWN((((5-95)*(AF47-0))/(30000-0))+95,0)),"") -> 64
B48: LIPU COLIMA | D48: P.GOIYTIA MANZANO ALONSO FAVI | E48: =VLOOKUP(D48,VIAJES!$D:$E,2,FALSE) -> 8 | F48: =VLOOKUP(D48,VIAJES!$D:$F,3,FALSE) -> 0.040972222 | G48: =VLOOKUP(D48,VIAJES!$D:$G,4,FALSE) -> 0.11736111 | H48: =VLOOKUP(D48,VIAJES!$D:$H,5,FALSE) -> 92.9 | S48: =IFERROR(INDEX(EVENTOS!$D:$D,MATCH(SCORE!S$2&" "&SCORE!$D48,EVENTOS!$F:$F,0)),0) -> 2 | T48: =IFERROR(INDEX(EVENTOS!$D:$D,MATCH(SCORE!T$2&" "&SCORE!$D48,EVENTOS!$F:$F,0)),0) -> 0 | U48: =IFERROR(INDEX(EVENTOS!$D:$D,MATCH(SCORE!U$2&" "&SCORE!$D48,EVENTOS!$F:$F,0)),0) -> 0 | V48: =IFERROR(INDEX(EVENTOS!$D:$D,MATCH(SCORE!V$2&" "&SCORE!$D48,EVENTOS!$F:$F,0)),0) -> 0 | W48: =IFERROR(INDEX(EVENTOS!$D:$D,MATCH(SCORE!W$2&" "&SCORE!$D48,EVENTOS!$F:$F,0)),0) -> 0 | X48: =IFERROR(INDEX(EVENTOS!$D:$D,MATCH(SCORE!X$2&" "&SCORE!$D48,EVENTOS!$F:$F,0)),0) -> 0 | Y48: =SUMIFS(EVENTOS!$D:$D, EVENTOS!$B:$B, D48, EVENTOS!$E:$E, "*GirAlto*") -> 0 | Z48: =SUMIFS(EVENTOS!$D:$D, EVENTOS!$B:$B, D48, EVENTOS!$E:$E, "*GirMed*") -> 0 | AA48: =SUMIFS(EVENTOS!$D:$D, EVENTOS!$B:$B, D48, EVENTOS!$E:$E, "*GirBajo*") -> 0 | AB48: =IFERROR(INDEX(EVENTOS!$D:$D,MATCH(SCORE!AB$2&" "&SCORE!$D48,EVENTOS!$F:$F,0)),0) -> 0 | AC48: =IFERROR(INDEX(EVENTOS!$D:$D,MATCH(SCORE!AC$2&" "&SCORE!$D48,EVENTOS!$F:$F,0)),0) -> 0 | AD48: =IFERROR(INDEX(EVENTOS!$D:$D,MATCH(SCORE!AD$2&" "&SCORE!$D48,EVENTOS!$F:$F,0)),0) -> 3 | AE48: =((S48+V48+Y48+AB48)*50)+((T48+W48+Z48+AC48)*25)+((U48+X48+AA48+AD48)*5) -> 115 | AF48: =AE48/(G48*24)*100 -> 4082.8402 | AG48: =IF(D48<>"",IF(AF48>=30000,5,ROUNDDOWN((((5-95)*(AF48-0))/(30000-0))+95,0)),"") -> 82
B49: LIPU COLIMA | D49: P.GONZALEZ GILDO EFRAIN | E49: =VLOOKUP(D49,VIAJES!$D:$E,2,FALSE) -> 5 | F49: =VLOOKUP(D49,VIAJES!$D:$F,3,FALSE) -> 0.01875 | G49: =VLOOKUP(D49,VIAJES!$D:$G,4,FALSE) -> 0.092361111 | H49: =VLOOKUP(D49,VIAJES!$D:$H,5,FALSE) -> 100.08 | S49: =IFERROR(INDEX(EVENTOS!$D:$D,MATCH(SCORE!S$2&" "&SCORE!$D49,EVENTOS!$F:$F,0)),0) -> 1 | T49: =IFERROR(INDEX(EVENTOS!$D:$D,MATCH(SCORE!T$2&" "&SCORE!$D49,EVENTOS!$F:$F,0)),0) -> 0 | U49: =IFERROR(INDEX(EVENTOS!$D:$D,MATCH(SCORE!U$2&" "&SCORE!$D49,EVENTOS!$F:$F,0)),0) -> 0 | V49: =IFERROR(INDEX(EVENTOS!$D:$D,MATCH(SCORE!V$2&" "&SCORE!$D49,EVENTOS!$F:$F,0)),0) -> 0 | W49: =IFERROR(INDEX(EVENTOS!$D:$D,MATCH(SCORE!W$2&" "&SCORE!$D49,EVENTOS!$F:$F,0)),0) -> 0 | X49: =IFERROR(INDEX(EVENTOS!$D:$D,MATCH(SCORE!X$2&" "&SCORE!$D49,EVENTOS!$F:$F,0)),0) -> 0 | Y49: =SUMIFS(EVENTOS!$D:$D, EVENTOS!$B:$B, D49, EVENTOS!$E:$E, "*GirAlto*") -> 0 | Z49: =SUMIFS(EVENTOS!$D:$D, EVENTOS!$B:$B, D49, EVENTOS!$E:$E, "*GirMed*") -> 0 | AA49: =SUMIFS(EVENTOS!$D:$D, EVENTOS!$B:$B, D49, EVENTOS!$E:$E, "*GirBajo*") -> 2 | AB49: =IFERROR(INDEX(EVENTOS!$D:$D,MATCH(SCORE!AB$2&" "&SCORE!$D49,EVENTOS!$F:$F,0)),0) -> 0 | AC49: =IFERROR(INDEX(EVENTOS!$D:$D,MATCH(SCORE!AC$2&" "&SCORE!$D49,EVENTOS!$F:$F,0)),0) -> 0 | AD49: =IFERROR(INDEX(EVENTOS!$D:$D,MATCH(SCORE!AD$2&" "&SCORE!$D49,EVENTOS!$F:$F,0)),0) -> 3 | AE49: =((S49+V49+Y49+AB49)*50)+((T49+W49+Z49+AC49)*25)+((U49+X49+AA49+AD49)*5) -> 75 | AF49: =AE49/(G49*24)*100 -> 3383.4586 | AG49: =IF(D49<>"",IF(AF49>=30000,5,ROUNDDOWN((((5-95)*(AF49-0))/(30000-0))+95,0)),"") -> 84
B50: LIPU COLIMA | D50: P.GUERRERO BELTRAN CARLOS ALEJ | E50: =VLOOKUP(D50,VIAJES!$D:$E,2,FALSE) -> 4 | F50: =VLOOKUP(D50,VIAJES!$D:$F,3,FALSE) -> 0.017361111 | G50: =VLOOKUP(D50,VIAJES!$D:$G,4,FALSE) -> 0.048611111 | H50: =VLOOKUP(D50,VIAJES!$D:$H,5,FALSE) -> 46.65 | S50: =IFERROR(INDEX(EVENTOS!$D:$D,MATCH(SCORE!S$2&" "&SCORE!$D50,EVENTOS!$F:$F,0)),0) -> 0 | T50: =IFERROR(INDEX(EVENTOS!$D:$D,MATCH(SCORE!T$2&" "&SCORE!$D50,EVENTOS!$F:$F,0)),0) -> 0 | U50: =IFERROR(INDEX(EVENTOS!$D:$D,MATCH(SCORE!U$2&" "&SCORE!$D50,EVENTOS!$F:$F,0)),0) -> 0 | V50: =IFERROR(INDEX(EVENTOS!$D:$D,MATCH(SCORE!V$2&" "&SCORE!$D50,EVENTOS!$F:$F,0)),0) -> 0 | W50: =IFERROR(INDEX(EVENTOS!$D:$D,MATCH(SCORE!W$2&" "&SCORE!$D50,EVENTOS!$F:$F,0)),0) -> 0 | X50: =IFERROR(INDEX(EVENTOS!$D:$D,MATCH(SCORE!X$2&" "&SCORE!$D50,EVENTOS!$F:$F,0)),0) -> 0 | Y50: =SUMIFS(EVENTOS!$D:$D, EVENTOS!$B:$B, D50, EVENTOS!$E:$E, "*GirAlto*") -> 0 | Z50: =SUMIFS(EVENTOS!$D:$D, EVENTOS!$B:$B, D50, EVENTOS!$E:$E, "*GirMed*") -> 0 | AA50: =SUMIFS(EVENTOS!$D:$D, EVENTOS!$B:$B, D50, EVENTOS!$E:$E, "*GirBajo*") -> 0 | AB50: =IFERROR(INDEX(EVENTOS!$D:$D,MATCH(SCORE!AB$2&" "&SCORE!$D50,EVENTOS!$F:$F,0)),0) -> 0 | AC50: =IFERROR(INDEX(EVENTOS!$D:$D,MATCH(SCORE!AC$2&" "&SCORE!$D50,EVENTOS!$F:$F,0)),0) -> 0 | AD50: =IFERROR(INDEX(EVENTOS!$D:$D,MATCH(SCORE!AD$2&" "&SCORE!$D50,EVENTOS!$F:$F,0)),0) -> 0 | AE50: =((S50+V50+Y50+AB50)*50)+((T50+W50+Z50+AC50)*25)+((U50+X50+AA50+AD50)*5) -> 0 | AF50: =AE50/(G50*24)*100 -> 0 | AG50: =IF(D50<>"",IF(AF50>=30000,5,ROUNDDOWN((((5-95)*(AF50-0))/(30000-0))+95,0)),"") -> 95
B51: LIPU COLIMA | D51: P.LEE GUTIERREZ JOSE GUADALUPE | E51: =VLOOKUP(D51,VIAJES!$D:$E,2,FALSE) -> 4 | F51: =VLOOKUP(D51,VIAJES!$D:$F,3,FALSE) -> 0.013888889 | G51: =VLOOKUP(D51,VIAJES!$D:$G,4,FALSE) -> 0.098611111 | H51: =VLOOKUP(D51,VIAJES!$D:$H,5,FALSE) -> 108.53 | S51: =IFERROR(INDEX(EVENTOS!$D:$D,MATCH(SCORE!S$2&" "&SCORE!$D51,EVENTOS!$F:$F,0)),0) -> 0 | T51: =IFERROR(INDEX(EVENTOS!$D:$D,MATCH(SCORE!T$2&" "&SCORE!$D51,EVENTOS!$F:$F,0)),0) -> 0 | U51: =IFERROR(INDEX(EVENTOS!$D:$D,MATCH(SCORE!U$2&" "&SCORE!$D51,EVENTOS!$F:$F,0)),0) -> 0 | V51: =IFERROR(INDEX(EVENTOS!$D:$D,MATCH(SCORE!V$2&" "&SCORE!$D51,EVENTOS!$F:$F,0)),0) -> 0 | W51: =IFERROR(INDEX(EVENTOS!$D:$D,MATCH(SCORE!W$2&" "&SCORE!$D51,EVENTOS!$F:$F,0)),0) -> 0 | X51: =IFERROR(INDEX(EVENTOS!$D:$D,MATCH(SCORE!X$2&" "&SCORE!$D51,EVENTOS!$F:$F,0)),0) -> 0 | Y51: =SUMIFS(EVENTOS!$D:$D, EVENTOS!$B:$B, D51, EVENTOS!$E:$E, "*GirAlto*") -> 0 | Z51: =SUMIFS(EVENTOS!$D:$D, EVENTOS!$B:$B, D51, EVENTOS!$E:$E, "*GirMed*") -> 0 | AA51: =SUMIFS(EVENTOS!$D:$D, EVENTOS!$B:$B, D51, EVENTOS!$E:$E, "*GirBajo*") -> 1 | AB51: =IFERROR(INDEX(EVENTOS!$D:$D,MATCH(SCORE!AB$2&" "&SCORE!$D51,EVENTOS!$F:$F,0)),0) -> 0 | AC51: =IFERROR(INDEX(EVENTOS!$D:$D,MATCH(SCORE!AC$2&" "&SCORE!$D51,EVENTOS!$F:$F,0)),0) -> 0 | AD51: =IFERROR(INDEX(EVENTOS!$D:$D,MATCH(SCORE!AD$2&" "&SCORE!$D51,EVENTOS!$F:$F,0)),0) -> 7 | AE51: =((S51+V51+Y51+AB51)*50)+((T51+W51+Z51+AC51)*25)+((U51+X51+AA51+AD51)*5) -> 40 | AF51: =AE51/(G51*24)*100 -> 1690.1408 | AG51: =IF(D51<>"",IF(AF51>=30000,5,ROUNDDOWN((((5-95)*(AF51-0))/(30000-0))+95,0)),"") -> 89
B52: LIPU COLIMA | D52: P.NUÑIEZ TORRES RICARDO | E52: =VLOOKUP(D52,VIAJES!$D:$E,2,FALSE) -> 1 | F52: =VLOOKUP(D52,VIAJES!$D:$F,3,FALSE) -> 0.0034722222 | G52: =VLOOKUP(D52,VIAJES!$D:$G,4,FALSE) -> 0.0020833333 | H52: =VLOOKUP(D52,VIAJES!$D:$H,5,FALSE) -> 0.49 | S52: =IFERROR(INDEX(EVENTOS!$D:$D,MATCH(SCORE!S$2&" "&SCORE!$D52,EVENTOS!$F:$F,0)),0) -> 0 | T52: =IFERROR(INDEX(EVENTOS!$D:$D,MATCH(SCORE!T$2&" "&SCORE!$D52,EVENTOS!$F:$F,0)),0) -> 0 | U52: =IFERROR(INDEX(EVENTOS!$D:$D,MATCH(SCORE!U$2&" "&SCORE!$D52,EVENTOS!$F:$F,0)),0) -> 0 | V52: =IFERROR(INDEX(EVENTOS!$D:$D,MATCH(SCORE!V$2&" "&SCORE!$D52,EVENTOS!$F:$F,0)),0) -> 0 | W52: =IFERROR(INDEX(EVENTOS!$D:$D,MATCH(SCORE!W$2&" "&SCORE!$D52,EVENTOS!$F:$F,0)),0) -> 0 | X52: =IFERROR(INDEX(EVENTOS!$D:$D,MATCH(SCORE!X$2&" "&SCORE!$D52,EVENTOS!$F:$F,0)),0) -> 0 | Y52: =SUMIFS(EVENTOS!$D:$D, EVENTOS!$B:$B, D52, EVENTOS!$E:$E, "*GirAlto*") -> 0 | Z52: =SUMIFS(EVENTOS!$D:$D, EVENTOS!$B:$B, D52, EVENTOS!$E:$E, "*GirMed*") -> 0 | AA52: =SUMIFS(EVENTOS!$D:$D, EVENTOS!$B:$B, D52, EVENTOS!$E:$E, "*GirBajo*") -> 0 | AB52: =IFERROR(INDEX(EVENTOS!$D:$D,MATCH(SCORE!AB$2&" "&SCORE!$D52,EVENTOS!$F:$F,0)),0) -> 0 | AC52: =IFERROR(INDEX(EVENTOS!$D:$D,MATCH(SCORE!AC$2&" "&SCORE!$D52,EVENTOS!$F:$F,0)),0) -> 0 | AD52: =IFERROR(INDEX(EVENTOS!$D:$D,MATCH(SCORE!AD$2&" "&SCORE!$D52,EVENTOS!$F:$F,0)),0) -> 0 | AE52: =((S52+V52+Y52+AB52)*50)+((T52+W52+Z52+AC52)*25)+((U52+X52+AA52+AD52)*5) -> 0 | AF52: =AE52/(G52*24)*100 -> 0 | AG52: =IF(D52<>"",IF(AF52>=30000,5,ROUNDDOWN((((5-95)*(AF52-0))/(30000-0))+95,0)),"") -> 95
B53: LIPU COLIMA | D53: P.REYNOSO PEREZ CARLOS SALVADO | E53: =VLOOKUP(D53,VIAJES!$D:$E,2,FALSE) -> 1 | F53: =VLOOKUP(D53,VIAJES!$D:$F,3,FALSE) -> 0.015277778 | G53: =VLOOKUP(D53,VIAJES!$D:$G,4,FALSE) -> 0.059722222 | H53: =VLOOKUP(D53,VIAJES!$D:$H,5,FALSE) -> 68.7 | S53: =IFERROR(INDEX(EVENTOS!$D:$D,MATCH(SCORE!S$2&" "&SCORE!$D53,EVENTOS!$F:$F,0)),0) -> 1 | T53: =IFERROR(INDEX(EVENTOS!$D:$D,MATCH(SCORE!T$2&" "&SCORE!$D53,EVENTOS!$F:$F,0)),0) -> 0 | U53: =IFERROR(INDEX(EVENTOS!$D:$D,MATCH(SCORE!U$2&" "&SCORE!$D53,EVENTOS!$F:$F,0)),0) -> 0 | V53: =IFERROR(INDEX(EVENTOS!$D:$D,MATCH(SCORE!V$2&" "&SCORE!$D53,EVENTOS!$F:$F,0)),0) -> 0 | W53: =IFERROR(INDEX(EVENTOS!$D:$D,MATCH(SCORE!W$2&" "&SCORE!$D53,EVENTOS!$F:$F,0)),0) -> 0 | X53: =IFERROR(INDEX(EVENTOS!$D:$D,MATCH(SCORE!X$2&" "&SCORE!$D53,EVENTOS!$F:$F,0)),0) -> 0 | Y53: =SUMIFS(EVENTOS!$D:$D, EVENTOS!$B:$B, D53, EVENTOS!$E:$E, "*GirAlto*") -> 0 | Z53: =SUMIFS(EVENTOS!$D:$D, EVENTOS!$B:$B, D53, EVENTOS!$E:$E, "*GirMed*") -> 0 | AA53: =SUMIFS(EVENTOS!$D:$D, EVENTOS!$B:$B, D53, EVENTOS!$E:$E, "*GirBajo*") -> 0 | AB53: =IFERROR(INDEX(EVENTOS!$D:$D,MATCH(SCORE!AB$2&" "&SCORE!$D53,EVENTOS!$F:$F,0)),0) -> 0 | AC53: =IFERROR(INDEX(EVENTOS!$D:$D,MATCH(SCORE!AC$2&" "&SCORE!$D53,EVENTOS!$F:$F,0)),0) -> 0 | AD53: =IFERROR(INDEX(EVENTOS!$D:$D,MATCH(SCORE!AD$2&" "&SCORE!$D53,EVENTOS!$F:$F,0)),0) -> 0 | AE53: =((S53+V53+Y53+AB53)*50)+((T53+W53+Z53+AC53)*25)+((U53+X53+AA53+AD53)*5) -> 50 | AF53: =AE53/(G53*24)*100 -> 3488.3721 | AG53: =IF(D53<>"",IF(AF53>=30000,5,ROUNDDOWN((((5-95)*(AF53-0))/(30000-0))+95,0)),"") -> 84
B54: LIPU COLIMA | D54: P.ROMERO RAMIREZ ARMANDO | E54: =VLOOKUP(D54,VIAJES!$D:$E,2,FALSE) -> 5 | F54: =VLOOKUP(D54,VIAJES!$D:$F,3,FALSE) -> 0.034722222 | G54: =VLOOKUP(D54,VIAJES!$D:$G,4,FALSE) -> 0.12430556 | H54: =VLOOKUP(D54,VIAJES!$D:$H,5,FALSE) -> 112.3 | S54: =IFERROR(INDEX(EVENTOS!$D:$D,MATCH(SCORE!S$2&" "&SCORE!$D54,EVENTOS!$F:$F,0)),0) -> 2 | T54: =IFERROR(INDEX(EVENTOS!$D:$D,MATCH(SCORE!T$2&" "&SCORE!$D54,EVENTOS!$F:$F,0)),0) -> 0 | U54: =IFERROR(INDEX(EVENTOS!$D:$D,MATCH(SCORE!U$2&" "&SCORE!$D54,EVENTOS!$F:$F,0)),0) -> 0 | V54: =IFERROR(INDEX(EVENTOS!$D:$D,MATCH(SCORE!V$2&" "&SCORE!$D54,EVENTOS!$F:$F,0)),0) -> 0 | W54: =IFERROR(INDEX(EVENTOS!$D:$D,MATCH(SCORE!W$2&" "&SCORE!$D54,EVENTOS!$F:$F,0)),0) -> 0 | X54: =IFERROR(INDEX(EVENTOS!$D:$D,MATCH(SCORE!X$2&" "&SCORE!$D54,EVENTOS!$F:$F,0)),0) -> 0 | Y54: =SUMIFS(EVENTOS!$D:$D, EVENTOS!$B:$B, D54, EVENTOS!$E:$E, "*GirAlto*") -> 0 | Z54: =SUMIFS(EVENTOS!$D:$D, EVENTOS!$B:$B, D54, EVENTOS!$E:$E, "*GirMed*") -> 0 | AA54: =SUMIFS(EVENTOS!$D:$D, EVENTOS!$B:$B, D54, EVENTOS!$E:$E, "*GirBajo*") -> 0 | AB54: =IFERROR(INDEX(EVENTOS!$D:$D,MATCH(SCORE!AB$2&" "&SCORE!$D54,EVENTOS!$F:$F,0)),0) -> 0 | AC54: =IFERROR(INDEX(EVENTOS!$D:$D,MATCH(SCORE!AC$2&" "&SCORE!$D54,EVENTOS!$F:$F,0)),0) -> 0 | AD54: =IFERROR(INDEX(EVENTOS!$D:$D,MATCH(SCORE!AD$2&" "&SCORE!$D54,EVENTOS!$F:$F,0)),0) -> 0 | AE54: =((S54+V54+Y54+AB54)*50)+((T54+W54+Z54+AC54)*25)+((U54+X54+AA54+AD54)*5) -> 100 | AF54: =AE54/(G54*24)*100 -> 3351.9553 | AG54: =IF(D54<>"",IF(AF54>=30000,5,ROUNDDOWN((((5-95)*(AF54-0))/(30000-0))+95,0)),"") -> 84
